Workbook

Sheet PASSDOWN
A1: Rochelle Labeling Shift Passdown (Dashboard v2)
A2: Date | B2: 46078 | D2: Shift | E2: 3rd | G2: Supervisor | H2: Brian Crusoe | K2: Lines Covered | L2: 1-5 | N2: Total Cases | O2: =SUM($F$11:$F$15) -> 0 | Q2: Avg OEE | R2: =IFERROR(SUMPRODUCT($G$11:$G$15,$F$11:$F$15)/SUM($F$11:$F$15),"") | T2: Shift Minutes | U2: 480
A3: Scheduled HC | B3: 45 | D3: Present HC | E3: 38 | G3: Absent HC | H3: =IF(OR($B$3="",$E$3=""),"",$B$3-$E$3) -> 7 | Q3: Total OT Hrs | R3: =$T$6 -> 0
A5: LINE SUMMARY (enter key production stats) | N5: OVERTIME LIST (who came / who didn't)
N6: OT Showed | O6: =COUNTIF($R$11:$R$30,"Y") -> 0 | Q6: OT No-Show | R6: =COUNTIF($R$11:$R$30,"N") -> 0
A7: SHIFT HIGHLIGHTS (2–4 bullets): • • •
A10: Line | B10: Order # | C10: SKU | D10: Description | E10: Target Cases | F10: Actual Cases | G10: OEE | H10: TrakSYS DT (min) | I10: Why off target / Key constraint | J10: Next shift needs
A11: 1 | B11: =IFERROR(#REF!,"") | D11: =IFERROR(#REF!,"")
A12: 2 | B12: =IFERROR(#REF!,"") | D12: =IFERROR(#REF!,"")
A13: 3 | B13: =IFERROR(#REF!,"") | D13: =IFERROR(#REF!,"")
A14: 4 | B14: =IFERROR(#REF!,"") | D14: =IFERROR(#REF!,"")
A15: 5 | B15: =IFERROR(#REF!,"") | D15: =IFERROR(#REF!,"")
A16: TOTAL / WEIGHTED | E16: =SUM(E11:E15) -> 0 | F16: =SUM(F11:F15) -> 0 | G16: =IFERROR(SUMPRODUCT(G11:G15,F11:F15)/SUM(F11:F15),"") | H16: =SUM(H11:H15) -> 0
A18: TOP DOWNTIME / EVENTS (auto-pulls top 5 by minutes from EVENTS tab)
A19: Rank | B19: Minutes | C19: Line | D19: Area | E19: Issue / What happened | F19: Status | G19: Next step / Owner
A20: 1 | B20: =IF($M20="","",INDEX(EVENTS!$G$5:$G$204,MATCH($M20,EVENTS!$T$5:$T$204,0))) | C20: =IF($M20="","",INDEX(EVENTS!$C$5:$C$204,MATCH($M20,EVENTS!$T$5:$T$204,0))) | D20: =IF($M20="","",INDEX(EVENTS!$H$5:$H$204,MATCH($M20,EVENTS!$T$5:$T$204,0))) | E20: =IF($M20="","",INDEX(EVENTS!$I$5:$I$204,MATCH($M20,EVENTS!$T$5:$T$204,0))) | F20: =IF($M20="","",INDEX(EVENTS!$M$5:$M$204,MATCH($M20,EVENTS!$T$5:$T$204,0))) | G20: =IF($M20="","",INDEX(EVENTS!$N$5:$N$204,MATCH($M20,EVENTS!$T$5:$T$204,0))) | M20: =IFERROR(LARGE(EVENTS!$T$5:$T$204,1),"")
A21: 2 | B21: =IF($M21="","",INDEX(EVENTS!$G$5:$G$204,MATCH($M21,EVENTS!$T$5:$T$204,0))) | C21: =IF($M21="","",INDEX(EVENTS!$C$5:$C$204,MATCH($M21,EVENTS!$T$5:$T$204,0))) | D21: =IF($M21="","",INDEX(EVENTS!$H$5:$H$204,MATCH($M21,EVENTS!$T$5:$T$204,0))) | E21: =IF($M21="","",INDEX(EVENTS!$I$5:$I$204,MATCH($M21,EVENTS!$T$5:$T$204,0))) | F21: =IF($M21="","",INDEX(EVENTS!$M$5:$M$204,MATCH($M21,EVENTS!$T$5:$T$204,0))) | G21: =IF($M21="","",INDEX(EVENTS!$N$5:$N$204,MATCH($M21,EVENTS!$T$5:$T$204,0))) | M21: =IFERROR(LARGE(EVENTS!$T$5:$T$204,2),"")
A22: 3 | B22: =IF($M22="","",INDEX(EVENTS!$G$5:$G$204,MATCH($M22,EVENTS!$T$5:$T$204,0))) | C22: =IF($M22="","",INDEX(EVENTS!$C$5:$C$204,MATCH($M22,EVENTS!$T$5:$T$204,0))) | D22: =IF($M22="","",INDEX(EVENTS!$H$5:$H$204,MATCH($M22,EVENTS!$T$5:$T$204,0))) | E22: =IF($M22="","",INDEX(EVENTS!$I$5:$I$204,MATCH($M22,EVENTS!$T$5:$T$204,0))) | F22: =IF($M22="","",INDEX(EVENTS!$M$5:$M$204,MATCH($M22,EVENTS!$T$5:$T$204,0))) | G22: =IF($M22="","",INDEX(EVENTS!$N$5:$N$204,MATCH($M22,EVENTS!$T$5:$T$204,0))) | M22: =IFERROR(LARGE(EVENTS!$T$5:$T$204,3),"")
A23: 4 | B23: =IF($M23="","",INDEX(EVENTS!$G$5:$G$204,MATCH($M23,EVENTS!$T$5:$T$204,0))) | C23: =IF($M23="","",INDEX(EVENTS!$C$5:$C$204,MATCH($M23,EVENTS!$T$5:$T$204,0))) | D23: =IF($M23="","",INDEX(EVENTS!$H$5:$H$204,MATCH($M23,EVENTS!$T$5:$T$204,0))) | E23: =IF($M23="","",INDEX(EVENTS!$I$5:$I$204,MATCH($M23,EVENTS!$T$5:$T$204,0))) | F23: =IF($M23="","",INDEX(EVENTS!$M$5:$M$204,MATCH($M23,EVENTS!$T$5:$T$204,0))) | G23: =IF($M23="","",INDEX(EVENTS!$N$5:$N$204,MATCH($M23,EVENTS!$T$5:$T$204,0))) | M23: =IFERROR(LARGE(EVENTS!$T$5:$T$204,4),"")
A24: 5 | B24: =IF($M24="","",INDEX(EVENTS!$G$5:$G$204,MATCH($M24,EVENTS!$T$5:$T$204,0))) | C24: =IF($M24="","",INDEX(EVENTS!$C$5:$C$204,MATCH($M24,EVENTS!$T$5:$T$204,0))) | D24: =IF($M24="","",INDEX(EVENTS!$H$5:$H$204,MATCH($M24,EVENTS!$T$5:$T$204,0))) | E24: =IF($M24="","",INDEX(EVENTS!$I$5:$I$204,MATCH($M24,EVENTS!$T$5:$T$204,0))) | F24: =IF($M24="","",INDEX(EVENTS!$M$5:$M$204,MATCH($M24,EVENTS!$T$5:$T$204,0))) | G24: =IF($M24="","",INDEX(EVENTS!$N$5:$N$204,MATCH($M24,EVENTS!$T$5:$T$204,0))) | M24: =IFERROR(LARGE(EVENTS!$T$5:$T$204,5),"")
A26: CHANGEOVER PREP (90-min lead) — update Next Order + prep status in CHANGEOVERS tab
A27: Line | B27: Current Order # | C27: Current SKU | D27: Next Order # | E27: Next SKU | F27: Remaining Cases | G27: Est Min Remaining | H27: Prep Status | I27: Materials Staged | J27: BRITE Done | K27: Notes
A28: =CHANGEOVERS!A6 -> 1 | B28: =CHANGEOVERS!B6 | C28: =CHANGEOVERS!C6 -> 0 | D28: =IFERROR(#REF!,"") | E28: =IFERROR(#REF!,"") | F28: =CHANGEOVERS!H6 | G28: =CHANGEOVERS!I6 | H28: =CHANGEOVERS!J6 | I28: =CHANGEOVERS!K6 -> 0 | J28: =CHANGEOVERS!L6 -> 0 | K28: =CHANGEOVERS!M6 -> #REF!
A29: =CHANGEOVERS!A7 -> 2 | B29: =CHANGEOVERS!B7 | C29: =CHANGEOVERS!C7 -> 0 | D29: =IFERROR(#REF!,"") | E29: =IFERROR(#REF!,"") | F29: =CHANGEOVERS!H7 | G29: =CHANGEOVERS!I7 | H29: =CHANGEOVERS!J7 | I29: =CHANGEOVERS!K7 -> 0 | J29: =CHANGEOVERS!L7 -> 0 | K29: =CHANGEOVERS!M7 -> #REF!
A30: =CHANGEOVERS!A8 -> 3 | B30: =CHANGEOVERS!B8 | C30: =CHANGEOVERS!C8 -> 0 | D30: =IFERROR(#REF!,"") | E30: =IFERROR(#REF!,"") | F30: =CHANGEOVERS!H8 | G30: =CHANGEOVERS!I8 | H30: =CHANGEOVERS!J8 | I30: =CHANGEOVERS!K8 -> 0 | J30: =CHANGEOVERS!L8 -> 0 | K30: =CHANGEOVERS!M8 -> #REF!
A31: =CHANGEOVERS!A9 -> 4 | B31: =CHANGEOVERS!B9 | C31: =CHANGEOVERS!C9 -> 0 | D31: =IFERROR(#REF!,"") | E31: =IFERROR(#REF!,"") | F31: =CHANGEOVERS!H9 | G31: =CHANGEOVERS!I9 | H31: =CHANGEOVERS!J9 | I31: =CHANGEOVERS!K9 -> 0 | J31: =CHANGEOVERS!L9 -> 0 | K31: =CHANGEOVERS!M9 -> #REF!
A32: =CHANGEOVERS!A10 -> 5 | B32: =CHANGEOVERS!B10 | C32: =CHANGEOVERS!C10 -> 0 | D32: =IFERROR(#REF!,"") | E32: =IFERROR(#REF!,"") | F32: =CHANGEOVERS!H10 | G32: =CHANGEOVERS!I10 | H32: =CHANGEOVERS!J10 | I32: =CHANGEOVERS!K10 -> 0 | J32: =CHANGEOVERS!L10 -> 0 | K32: =CHANGEOVERS!M10 -> #REF!
A36: PRODUCTION SCHEDULE BY PRIORITY
A37: Line | B37: Pri | C37: Current WO | D37: Description | E37: Next WO | F37: Next Desc | G37: % Complete | H37: Hard Stop | I37: Schedule Notes
A38: 1 | B38: 1 | C38: =#REF! -> #REF! | D38: =#REF! -> #REF! | E38: =#REF! -> #REF! | F38: =#REF! -> #REF! | G38: =IFERROR(INDEX(#REF!,MATCH(11,#REF!,0)),"") | H38: =IF(#REF!=0,"",#REF!) -> #REF! | I38: =IF(#REF!=0,"",#REF!) -> #REF!
A39: 2 | B39: 2 | C39: =#REF! -> #REF! | D39: =#REF! -> #REF! | E39: =#REF! -> #REF! | F39: =#REF! -> #REF! | G39: =IFERROR(INDEX(#REF!,MATCH(21,#REF!,0)),"") | H39: =IF(#REF!=0,"",#REF!) -> #REF! | I39: =IF(#REF!=0,"",#REF!) -> #REF!
A40: 4 | B40: 3 | C40: =#REF! -> #REF! | D40: =#REF! -> #REF! | E40: =#REF! -> #REF! | F40: =#REF! -> #REF! | G40: =IFERROR(INDEX(#REF!,MATCH(41,#REF!,0)),"") | H40: =IF(#REF!=0,"",#REF!) -> #REF! | I40: =IF(#REF!=0,"",#REF!) -> #REF!
A41: 3 | B41: 4 | C41: =#REF! -> #REF! | D41: =#REF! -> #REF! | E41: =#REF! -> #REF! | F41: =#REF! -> #REF! | G41: =IFERROR(INDEX(#REF!,MATCH(31,#REF!,0)),"") | H41: =IF(#REF!=0,"",#REF!) -> #REF! | I41: =IF(#REF!=0,"",#REF!) -> #REF!
A42: 5 | B42: 5 | C42: =#REF! -> #REF! | D42: =#REF! -> #REF! | E42: =#REF! -> #REF! | F42: =#REF! -> #REF! | G42: =IFERROR(INDEX(#REF!,MATCH(51,#REF!,0)),"") | H42: =IF(#REF!=0,"",#REF!) -> #REF! | I42: =IF(#REF!=0,"",#REF!) -> #REF!
A44: Daily use: update Date+Shift at top → Staffing auto-populates Crew Log → Crew Roster, Schedule, and Changeovers update automatically. Grade lives in CREW_LOG only.

Sheet SCHEDULE
A1: Daily Production Schedule
A2: Date | B2: 46078 | D2: Shift | E2: 3rd | G2: Line Priority | H2: 1-2-4-3-5 | N2: Line | O2: Priority
N3: 1 | O3: 1
A4: Line | B4: Priority | C4: Work Order # | D4: Description | E4: Total Cases | F4: Shifts | G4: Cases Completed | H4: Target/Shift | I4: % Complete | J4: Seq | K4: Notes | L4: Hard Stop | M4: WO Made | N4: 2 | O4: 2
A5: 1 | B5: 1 | C5: 2005210 | D5: 6/29OZ_DM WK GOLD CORN | E5: 10310 | F5: 2 | G5: 2203 | H5: 3700 | I5: =IF(OR(E5="TBD",E5="",E5=0),0,G5/E5) -> 0.21367604 | J5: 1 | M5: yes | N5: 4 | O5: 3 | V5: =IF(A5="","",A5*100+J5) -> 101 | W5: =IF(I5>=1,0,1) -> 1 | X5: =IF(W5=1,COUNTIFS($A$5:$A$16,A5,$V$5:$V$16,"<="&V5,$W$5:$W$16,1),"") -> 1 | Y5: =IF(X5="","",A5*10+X5) -> 11
A6: 2 | B6: 2 | C6: 2000376 | D6: 1/8-15.25OZ_DM WK GOLD CORN | E6: 70500 | F6: 3 | G6: 1768 | H6: 7800 | I6: =IF(OR(E6="TBD",E6="",E6=0),0,G6/E6) -> 0.025078014 | J6: 1 | M6: yes | N6: 3 | O6: 4 | V6: =IF(A6="","",A6*100+J6) -> 201 | W6: =IF(I6>=1,0,1) -> 1 | X6: =IF(W6=1,COUNTIFS($A$5:$A$16,A6,$V$5:$V$16,"<="&V6,$W$5:$W$16,1),"") -> 1 | Y6: =IF(X6="","",A6*10+X6) -> 21
A7: 3 | B7: 4 | C7: 2001312 | D7: 24/14.75OZ_DM SSCRM GLD CRN | E7: 4590 | F7: 1 | G7: 1421 | H7: 6000 | I7: =IF(OR(E7="TBD",E7="",E7=0),0,G7/E7) -> 0.30958606 | J7: 1 | M7: yes | N7: 5 | O7: 5 | V7: =IF(A7="","",A7*100+J7) -> 301 | W7: =IF(I7>=1,0,1) -> 1 | X7: =IF(W7=1,COUNTIFS($A$5:$A$16,A7,$V$5:$V$16,"<="&V7,$W$5:$W$16,1),"") -> 1 | Y7: =IF(X7="","",A7*10+X7) -> 31
A8: 3 | B8: 4 | C8: 2000901 | D8: 12/15.25OZ_DM GREEN LIMA BEANS | E8: 4800 | F8: 1 | G8: 0 | H8: 6000 | I8: =IF(OR(E8="TBD",E8="",E8=0),0,G8/E8) -> 0 | J8: 2 | M8: yes | V8: =IF(A8="","",A8*100+J8) -> 302 | W8: =IF(I8>=1,0,1) -> 1 | X8: =IF(W8=1,COUNTIFS($A$5:$A$16,A8,$V$5:$V$16,"<="&V8,$W$5:$W$16,1),"") -> 2 | Y8: =IF(X8="","",A8*10+X8) -> 32
A9: 3 | B9: 4 | C9: 2000899 | D9: 12/15.25OZ_DM WK WHITE CORN | E9: 5000 | F9: 1 | G9: 0 | H9: 6000 | I9: =IF(OR(E9="TBD",E9="",E9=0),0,G9/E9) -> 0 | J9: 3 | M9: yes | V9: =IF(A9="","",A9*100+J9) -> 303 | W9: =IF(I9>=1,0,1) -> 1 | X9: =IF(W9=1,COUNTIFS($A$5:$A$16,A9,$V$5:$V$16,"<="&V9,$W$5:$W$16,1),"") -> 3 | Y9: =IF(X9="","",A9*10+X9) -> 33
A10: 3 | B10: 4 | C10: 2000883 | D10: 12/15.25OZ_DM WKGC LOSOD | E10: 5990 | F10: 2 | G10: 0 | H10: 6000 | I10: =IF(OR(E10="TBD",E10="",E10=0),0,G10/E10) -> 0 | J10: 4 | M10: yes | V10: =IF(A10="","",A10*100+J10) -> 304 | W10: =IF(I10>=1,0,1) -> 1 | X10: =IF(W10=1,COUNTIFS($A$5:$A$16,A10,$V$5:$V$16,"<="&V10,$W$5:$W$16,1),"") -> 4 | Y10: =IF(X10="","",A10*10+X10) -> 34
A11: 4 | B11: 3 | C11: 2002160 | D11: 6/4-14.5OZ_DM CUT GRN BEANS | E11: 2095 | F11: 1 | G11: 938 | H11: 2940 | I11: =IF(OR(E11="TBD",E11="",E11=0),0,G11/E11) -> 0.4477327 | J11: 1 | M11: yes | V11: =IF(A11="","",A11*100+J11) -> 401 | W11: =IF(I11>=1,0,1) -> 1 | X11: =IF(W11=1,COUNTIFS($A$5:$A$16,A11,$V$5:$V$16,"<="&V11,$W$5:$W$16,1),"") -> 1 | Y11: =IF(X11="","",A11*10+X11) -> 41
A12: 4 | B12: 3 | C12: 2002144 | D12: 6/4-15.25OZ_DM WHOLE KERNEL CORN | E12: 6000 | F12: 2 | G12: 0 | H12: 2940 | I12: =IF(OR(E12="TBD",E12="",E12=0),0,G12/E12) -> 0 | J12: 2 | M12: yes | V12: =IF(A12="","",A12*100+J12) -> 402 | W12: =IF(I12>=1,0,1) -> 1 | X12: =IF(W12=1,COUNTIFS($A$5:$A$16,A12,$V$5:$V$16,"<="&V12,$W$5:$W$16,1),"") -> 2 | Y12: =IF(X12="","",A12*10+X12) -> 42
A13: 4 | B13: 3 | C13: 2002159 | D13: 6/4-14.5OZ_DM FS GREEN BEANS | E13: 325 | F13: 2 | G13: 0 | H13: 2940 | I13: =IF(OR(E13="TBD",E13="",E13=0),0,G13/E13) -> 0 | J13: 3 | M13: yes | V13: =IF(A13="","",A13*100+J13) -> 403 | W13: =IF(I13>=1,0,1) -> 1 | X13: =IF(W13=1,COUNTIFS($A$5:$A$16,A13,$V$5:$V$16,"<="&V13,$W$5:$W$16,1),"") -> 3 | Y13: =IF(X13="","",A13*10+X13) -> 43
A14: 5 | B14: 5 | C14: 2005188 | D14: 12/11OZ_DM VP WHITE SHOEPEG CORN | E14: 6700 | F14: 1 | G14: 4403 | H14: 5833 | I14: =IF(OR(E14="TBD",E14="",E14=0),0,G14/E14) -> 0.65716418 | J14: 1 | K14: changing over | M14: yes | V14: =IF(A14="","",A14*100+J14) -> 501 | W14: =IF(I14>=1,0,1) -> 1 | X14: =IF(W14=1,COUNTIFS($A$5:$A$16,A14,$V$5:$V$16,"<="&V14,$W$5:$W$16,1),"") -> 1 | Y14: =IF(X14="","",A14*10+X14) -> 51
A15: 5 | B15: 5 | C15: 2005383 | D15: 12/11OZ_DM VP WK MEX CORN | E15: 4500 | F15: 1 | G15: 0 | H15: 5833 | I15: =IF(OR(E15="TBD",E15="",E15=0),0,G15/E15) -> 0 | J15: 2 | K15: min 4500/ run to 9000 then change back | M15: yes | V15: =IF(A15="","",A15*100+J15) -> 502 | W15: =IF(I15>=1,0,1) -> 1 | X15: =IF(W15=1,COUNTIFS($A$5:$A$16,A15,$V$5:$V$16,"<="&V15,$W$5:$W$16,1),"") -> 2 | Y15: =IF(X15="","",A15*10+X15) -> 52
A16: 5 | B16: 5 | C16: 2005188 | D16: 12/11OZ_DM VP WHITE SHOEPEG CORN | E16: TBD | F16: 1 | G16: 0 | H16: 5833 | I16: =IF(OR(E16="TBD",E16="",E16=0),0,G16/E16) -> 0 | J16: 3 | K16: hard stop @600 | L16: hard stop @600 | V16: =IF(A16="","",A16*100+J16) -> 503 | W16: =IF(I16>=1,0,1) -> 1 | X16: =IF(W16=1,COUNTIFS($A$5:$A$16,A16,$V$5:$V$16,"<="&V16,$W$5:$W$16,1),"") -> 3 | Y16: =IF(X16="","",A16*10+X16) -> 53
A18: Daily Production Schedule
A19: Date | B19: 46079 | D19: Shift | E19: 3rd | G19: Line Priority | H19: 1-2-4-3-5
A21: Line | B21: Priority | C21: Work Order # | D21: Description | E21: Total Cases | F21: Shifts | G21: Cases Completed | H21: Target/Shift | I21: % Complete | J21: Seq | K21: Notes | L21: Hard Stop | M21: WO Made
A22: 1 | B22: 1 | C22: 2005210 | D22: 6/29OZ_DM WK GOLD CORN | E22: 1315 | F22: 2 | G22: 0 | H22: 3700 | I22: =IF(OR(E22="TBD",E22="",E22=0),0,G22/E22) -> 0 | J22: 1 | M22: yes | V22: =IF(A22="","",A22*100+J22) -> 101 | W22: =IF(I22>=1,0,1) -> 1 | X22: =IF(W22=1,COUNTIFS($A$22:$A$33,A22,$V$22:$V$33,"<="&V22,$W$22:$W$33,1),"") -> 1 | Y22: =IF(X22="","",A22*10+X22) -> 11
A23: 1 | B23: 1 | C23: 2005209 | D23: 6/28OZ_DM CUT GREEN BEANS | E23: 8780 | G23: 0 | H23: 3700 | I23: =IF(OR(E23="TBD",E23="",E23=0),0,G23/E23) -> 0 | J23: 2 | M23: yes | V23: =IF(A23="","",A23*100+J23) -> 102 | W23: =IF(I23>=1,0,1) -> 1 | X23: =IF(W23=1,COUNTIFS($A$22:$A$33,A23,$V$22:$V$33,"<="&V23,$W$22:$W$33,1),"") -> 2 | Y23: =IF(X23="","",A23*10+X23) -> 12
A24: 2 | B24: 2 | C24: 2000376 | D24: 1/8-15.25OZ_DM WK GOLD CORN | E24: 38940 | F24: 2 | G24: 0 | H24: 7800 | I24: =IF(OR(E24="TBD",E24="",E24=0),0,G24/E24) -> 0 | J24: 1 | M24: yes | V24: =IF(A24="","",A24*100+J24) -> 201 | W24: =IF(I24>=1,0,1) -> 1 | X24: =IF(W24=1,COUNTIFS($A$22:$A$33,A24,$V$22:$V$33,"<="&V24,$W$22:$W$33,1),"") -> 1 | Y24: =IF(X24="","",A24*10+X24) -> 21
A25: 2 | B25: 2 | C25: 2000332 | D25: 1/8-15OZ_DM SWEET PEAS | E25: 9750 | F25: 1 | G25: 0 | H25: 7800 | I25: =IF(OR(E25="TBD",E25="",E25=0),0,G25/E25) -> 0 | J25: 2 | V25: =IF(A25="","",A25*100+J25) -> 202 | W25: =IF(I25>=1,0,1) -> 1 | X25: =IF(W25=1,COUNTIFS($A$22:$A$33,A25,$V$22:$V$33,"<="&V25,$W$22:$W$33,1),"") -> 2 | Y25: =IF(X25="","",A25*10+X25) -> 22
A26: 2 | B26: 2 | C26: 2005818 | D26: 1/8-15.25OZ_DM TP VYS SWT PEAS | E26: 9750 | F26: 1 | G26: 0 | H26: 7800 | I26: =IF(OR(E26="TBD",E26="",E26=0),0,G26/E26) -> 0 | J26: 3 | V26: =IF(A26="","",A26*100+J26) -> 203 | W26: =IF(I26>=1,0,1) -> 1 | X26: =IF(W26=1,COUNTIFS($A$22:$A$33,A26,$V$22:$V$33,"<="&V26,$W$22:$W$33,1),"") -> 3 | Y26: =IF(X26="","",A26*10+X26) -> 23
A27: 2 | B27: 2 | C27: 2001872 | D27: 1/12-15.25OZ_DM WK CORN | E27: 2000 | F27: 1 | G27: 0 | H27: 7800 | I27: =IF(OR(E27="TBD",E27="",E27=0),0,G27/E27) -> 0 | J27: 4 | V27: =IF(A27="","",A27*100+J27) -> 204 | W27: =IF(I27>=1,0,1) -> 1 | X27: =IF(W27=1,COUNTIFS($A$22:$A$33,A27,$V$22:$V$33,"<="&V27,$W$22:$W$33,1),"") -> 4 | Y27: =IF(X27="","",A27*10+X27) -> 24
A28: 3 | B28: 4 | C28: 2000883 | D28: 12/15.25OZ_DM WKGC LOSOD | E28: 3885 | F28: 1 | G28: 0 | H28: 6000 | I28: =IF(OR(E28="TBD",E28="",E28=0),0,G28/E28) -> 0 | J28: 1 | M28: yes | V28: =IF(A28="","",A28*100+J28) -> 301 | W28: =IF(I28>=1,0,1) -> 1 | X28: =IF(W28=1,COUNTIFS($A$22:$A$33,A28,$V$22:$V$33,"<="&V28,$W$22:$W$33,1),"") -> 1 | Y28: =IF(X28="","",A28*10+X28) -> 31
A29: 3 | B29: 4 | C29: 2000880 | D29: 12/15.25OZ_DM SW CRN PBL&RED | E29: 15000 | F29: 1 | G29: 0 | H29: 6000 | I29: =IF(OR(E29="TBD",E29="",E29=0),0,G29/E29) -> 0 | J29: 2 | V29: =IF(A29="","",A29*100+J29) -> 302 | W29: =IF(I29>=1,0,1) -> 1 | X29: =IF(W29=1,COUNTIFS($A$22:$A$33,A29,$V$22:$V$33,"<="&V29,$W$22:$W$33,1),"") -> 2 | Y29: =IF(X29="","",A29*10+X29) -> 32
A30: 3 | B30: 4 | C30: 2005817 | D30: 12/15.25OZ_DM TP V YNG SM SWT PEAS | E30: 4800 | F30: 1 | G30: 0 | H30: 6000 | I30: =IF(OR(E30="TBD",E30="",E30=0),0,G30/E30) -> 0 | J30: 3 | V30: =IF(A30="","",A30*100+J30) -> 303 | W30: =IF(I30>=1,0,1) -> 1 | X30: =IF(W30=1,COUNTIFS($A$22:$A$33,A30,$V$22:$V$33,"<="&V30,$W$22:$W$33,1),"") -> 3 | Y30: =IF(X30="","",A30*10+X30) -> 33
A31: 3 | B31: 4 | C31: 2005731 | D31: 12/14.75OZ_DM HARVEST CREAMED CORN | E31: 2000 | F31: 2 | G31: 0 | H31: 6000 | I31: =IF(OR(E31="TBD",E31="",E31=0),0,G31/E31) -> 0 | J31: 4 | V31: =IF(A31="","",A31*100+J31) -> 304 | W31: =IF(I31>=1,0,1) -> 1 | X31: =IF(W31=1,COUNTIFS($A$22:$A$33,A31,$V$22:$V$33,"<="&V31,$W$22:$W$33,1),"") -> 4 | Y31: =IF(X31="","",A31*10+X31) -> 34
A32: 4 | B32: 3 | C32: 2002159 | D32: 6/4-14.5OZ_DM FS GREEN BEANS | E32: 8825 | F32: 2 | G32: 0 | H32: 2940 | I32: =IF(OR(E32="TBD",E32="",E32=0),0,G32/E32) -> 0 | J32: 1 | M32: yes | V32: =IF(A32="","",A32*100+J32) -> 401 | W32: =IF(I32>=1,0,1) -> 1 | X32: =IF(W32=1,COUNTIFS($A$22:$A$33,A32,$V$22:$V$33,"<="&V32,$W$22:$W$33,1),"") -> 1 | Y32: =IF(X32="","",A32*10+X32) -> 41
A33: 5 | B33: 5 | C33: 2005532 | D33: 12/15.25OZ_DM HARVEST WK CORN | E33: 11600 | F33: 1 | G33: 0 | H33: 5833 | I33: =IF(OR(E33="TBD",E33="",E33=0),0,G33/E33) -> 0 | J33: 1 | M33: yes | V33: =IF(A33="","",A33*100+J33) -> 501 | W33: =IF(I33>=1,0,1) -> 1 | X33: =IF(W33=1,COUNTIFS($A$22:$A$33,A33,$V$22:$V$33,"<="&V33,$W$22:$W$33,1),"") -> 1 | Y33: =IF(X33="","",A33*10+X33) -> 51

Sheet CHANGEOVERS
A1: Changeover Prep Planner (90 min lead)
A2: Date | D2: Shift | G2: Prep Lead (min) | H2: 90
G3: Rate Mode | H3: As-of Time | J3: Manual CPH
A4: CHANGEOVER FORECAST / PREP — sheet calculates PREP NOW based on minutes remaining (lead time = cell J2)
A5: Line | B5: Current Order # | C5: Current SKU | D5: Next Order # | E5: Next SKU | F5: Manual CPH | G5: Rate Used CPH | H5: Remaining Cases | I5: Est Min Remaining | J5: Prep Status | K5: Materials Staged | L5: BRITE Done | M5: Notes | N5: Std CPH (helper) | O5: OEE (helper)
A6: 1 | B6: =PASSDOWN!B11 | C6: =PASSDOWN!C11 -> 0 | D6: =IFERROR(#REF!,"") | E6: =IFERROR(#REF!,"") | G6: =IF($J$3="Manual CPH",F6,IF($J$3="Std CPH x OEE",N6*IF(O6="",1,O6),N6)) -> 0 | H6: =IF(OR(PASSDOWN!E11="",PASSDOWN!F11=""),"",IF(PASSDOWN!E11-PASSDOWN!F11<0,0,PASSDOWN!E11-PASSDOWN!F11)) | I6: =IF(OR(H6="",G6="",G6<=0),"",IF(H6=0,0,H6/(G6/60))) | J6: =IF(H6="","",IF(H6=0,"CHANGEOVER",IF(I6="","",IF(I6<=$H$2,"PREP NOW","NO")))) | M6: =IF(AND(#REF!="",#REF!=""),"",IF(#REF!="",#REF!,IF(#REF!="",#REF!,#REF!&" | "&#REF!))) -> #REF! | N6: =IF($A6="","",IF($A6=1,REF!$H$2,IF($A6=2,REF!$H$3,IF($A6=3,REF!$H$4,IF($A6=4,REF!$H$5,IF($A6=5,REF!$H$6,"")))))) -> 0 | O6: =PASSDOWN!G11 -> 0
A7: 2 | B7: =PASSDOWN!B12 | C7: =PASSDOWN!C12 -> 0 | D7: =IFERROR(#REF!,"") | E7: =IFERROR(#REF!,"") | G7: =IF($J$3="Manual CPH",F7,IF($J$3="Std CPH x OEE",N7*IF(O7="",1,O7),N7)) -> 0 | H7: =IF(OR(PASSDOWN!E12="",PASSDOWN!F12=""),"",IF(PASSDOWN!E12-PASSDOWN!F12<0,0,PASSDOWN!E12-PASSDOWN!F12)) | I7: =IF(OR(H7="",G7="",G7<=0),"",IF(H7=0,0,H7/(G7/60))) | J7: =IF(H7="","",IF(H7=0,"CHANGEOVER",IF(I7="","",IF(I7<=$H$2,"PREP NOW","NO")))) | M7: =IF(AND(#REF!="",#REF!=""),"",IF(#REF!="",#REF!,IF(#REF!="",#REF!,#REF!&" | "&#REF!))) -> #REF! | N7: =IF($A7="","",IF($A7=1,REF!$H$2,IF($A7=2,REF!$H$3,IF($A7=3,REF!$H$4,IF($A7=4,REF!$H$5,IF($A7=5,REF!$H$6,"")))))) -> 0 | O7: =PASSDOWN!G12 -> 0
A8: 3 | B8: =PASSDOWN!B13 | C8: =PASSDOWN!C13 -> 0 | D8: =IFERROR(#REF!,"") | E8: =IFERROR(#REF!,"") | G8: =IF($J$3="Manual CPH",F8,IF($J$3="Std CPH x OEE",N8*IF(O8="",1,O8),N8)) -> 0 | H8: =IF(OR(PASSDOWN!E13="",PASSDOWN!F13=""),"",IF(PASSDOWN!E13-PASSDOWN!F13<0,0,PASSDOWN!E13-PASSDOWN!F13)) | I8: =IF(OR(H8="",G8="",G8<=0),"",IF(H8=0,0,H8/(G8/60))) | J8: =IF(H8="","",IF(H8=0,"CHANGEOVER",IF(I8="","",IF(I8<=$H$2,"PREP NOW","NO")))) | M8: =IF(AND(#REF!="",#REF!=""),"",IF(#REF!="",#REF!,IF(#REF!="",#REF!,#REF!&" | "&#REF!))) -> #REF! | N8: =IF($A8="","",IF($A8=1,REF!$H$2,IF($A8=2,REF!$H$3,IF($A8=3,REF!$H$4,IF($A8=4,REF!$H$5,IF($A8=5,REF!$H$6,"")))))) -> 0 | O8: =PASSDOWN!G13 -> 0
A9: 4 | B9: =PASSDOWN!B14 | C9: =PASSDOWN!C14 -> 0 | D9: =IFERROR(#REF!,"") | E9: =IFERROR(#REF!,"") | G9: =IF($J$3="Manual CPH",F9,IF($J$3="Std CPH x OEE",N9*IF(O9="",1,O9),N9)) -> 0 | H9: =IF(OR(PASSDOWN!E14="",PASSDOWN!F14=""),"",IF(PASSDOWN!E14-PASSDOWN!F14<0,0,PASSDOWN!E14-PASSDOWN!F14)) | I9: =IF(OR(H9="",G9="",G9<=0),"",IF(H9=0,0,H9/(G9/60))) | J9: =IF(H9="","",IF(H9=0,"CHANGEOVER",IF(I9="","",IF(I9<=$H$2,"PREP NOW","NO")))) | M9: =IF(AND(#REF!="",#REF!=""),"",IF(#REF!="",#REF!,IF(#REF!="",#REF!,#REF!&" | "&#REF!))) -> #REF! | N9: =IF($A9="","",IF($A9=1,REF!$H$2,IF($A9=2,REF!$H$3,IF($A9=3,REF!$H$4,IF($A9=4,REF!$H$5,IF($A9=5,REF!$H$6,"")))))) -> 0 | O9: =PASSDOWN!G14 -> 0
A10: 5 | B10: =PASSDOWN!B15 | C10: =PASSDOWN!C15 -> 0 | D10: =IFERROR(#REF!,"") | E10: =IFERROR(#REF!,"") | G10: =IF($J$3="Manual CPH",F10,IF($J$3="Std CPH x OEE",N10*IF(O10="",1,O10),N10)) -> 0 | H10: =IF(OR(PASSDOWN!E15="",PASSDOWN!F15=""),"",IF(PASSDOWN!E15-PASSDOWN!F15<0,0,PASSDOWN!E15-PASSDOWN!F15)) | I10: =IF(OR(H10="",G10="",G10<=0),"",IF(H10=0,0,H10/(G10/60))) | J10: =IF(H10="","",IF(H10=0,"CHANGEOVER",IF(I10="","",IF(I10<=$H$2,"PREP NOW","NO")))) | M10: =IF(AND(#REF!="",#REF!=""),"",IF(#REF!="",#REF!,IF(#REF!="",#REF!,#REF!&" | "&#REF!))) -> #REF! | N10: =IF($A10="","",IF($A10=1,REF!$H$2,IF($A10=2,REF!$H$3,IF($A10=3,REF!$H$4,IF($A10=4,REF!$H$5,IF($A10=5,REF!$H$6,"")))))) -> 0 | O10: =PASSDOWN!G15 -> 0
A12: Executed Changeover Log (optional)
A13: Date | B13: Shift | C13: Line | D13: From Order | E13: To Order | F13: Start | G13: End | H13: Duration (min) | I13: <=90? | J13: Reason / Notes
A14: =IF($C14="","", $B$2) | B14: =IF($C14="","", $E$2) | H14: =IF(OR(F14="",G14=""),"", (G14-F14)*1440) | I14: =IF(H14="","",IF(H14<= $H$2,"Y","N"))
A15: =IF($C15="","", $B$2) | B15: =IF($C15="","", $E$2) | H15: =IF(OR(F15="",G15=""),"", (G15-F15)*1440) | I15: =IF(H15="","",IF(H15<= $H$2,"Y","N"))
A16: =IF($C16="","", $B$2) | B16: =IF($C16="","", $E$2) | H16: =IF(OR(F16="",G16=""),"", (G16-F16)*1440) | I16: =IF(H16="","",IF(H16<= $H$2,"Y","N"))
A17: =IF($C17="","", $B$2) | B17: =IF($C17="","", $E$2) | H17: =IF(OR(F17="",G17=""),"", (G17-F17)*1440) | I17: =IF(H17="","",IF(H17<= $H$2,"Y","N"))
A18: =IF($C18="","", $B$2) | B18: =IF($C18="","", $E$2) | H18: =IF(OR(F18="",G18=""),"", (G18-F18)*1440) | I18: =IF(H18="","",IF(H18<= $H$2,"Y","N"))
A19: =IF($C19="","", $B$2) | B19: =IF($C19="","", $E$2) | H19: =IF(OR(F19="",G19=""),"", (G19-F19)*1440) | I19: =IF(H19="","",IF(H19<= $H$2,"Y","N"))
A20: =IF($C20="","", $B$2) | B20: =IF($C20="","", $E$2) | H20: =IF(OR(F20="",G20=""),"", (G20-F20)*1440) | I20: =IF(H20="","",IF(H20<= $H$2,"Y","N"))
A21: =IF($C21="","", $B$2) | B21: =IF($C21="","", $E$2) | H21: =IF(OR(F21="",G21=""),"", (G21-F21)*1440) | I21: =IF(H21="","",IF(H21<= $H$2,"Y","N"))
A22: =IF($C22="","", $B$2) | B22: =IF($C22="","", $E$2) | H22: =IF(OR(F22="",G22=""),"", (G22-F22)*1440) | I22: =IF(H22="","",IF(H22<= $H$2,"Y","N"))
A23: =IF($C23="","", $B$2) | B23: =IF($C23="","", $E$2) | H23: =IF(OR(F23="",G23=""),"", (G23-F23)*1440) | I23: =IF(H23="","",IF(H23<= $H$2,"Y","N"))
A24: =IF($C24="","", $B$2) | B24: =IF($C24="","", $E$2) | H24: =IF(OR(F24="",G24=""),"", (G24-F24)*1440) | I24: =IF(H24="","",IF(H24<= $H$2,"Y","N"))
A25: =IF($C25="","", $B$2) | B25: =IF($C25="","", $E$2) | H25: =IF(OR(F25="",G25=""),"", (G25-F25)*1440) | I25: =IF(H25="","",IF(H25<= $H$2,"Y","N"))
... A33: =IF($C33="","", $B$2) | B33: =IF($C33="","", $E$2) | H33: =IF(OR(F33="",G33=""),"", (G33-F33)*1440) | I33: =IF(H33="","",IF(H33<= $H$2,"Y","N"))
H34: =IF(OR(F34="",G34=""),"", (G34-F34)*1440) | I34: =IF(H34="","",IF(H34<= $H$2,"Y","N"))
H35: =IF(OR(F35="",G35=""),"", (G35-F35)*1440) | I35: =IF(H35="","",IF(H35<= $H$2,"Y","N"))
H36: =IF(OR(F36="",G36=""),"", (G36-F36)*1440) | I36: =IF(H36="","",IF(H36<= $H$2,"Y","N"))
H37: =IF(OR(F37="",G37=""),"", (G37-F37)*1440) | I37: =IF(H37="","",IF(H37<= $H$2,"Y","N"))
H38: =IF(OR(F38="",G38=""),"", (G38-F38)*1440) | I38: =IF(H38="","",IF(H38<= $H$2,"Y","N"))
H39: =IF(OR(F39="",G39=""),"", (G39-F39)*1440) | I39: =IF(H39="","",IF(H39<= $H$2,"Y","N"))
H40: =IF(OR(F40="",G40=""),"", (G40-F40)*1440) | I40: =IF(H40="","",IF(H40<= $H$2,"Y","N"))
H41: =IF(OR(F41="",G41=""),"", (G41-F41)*1440) | I41: =IF(H41="","",IF(H41<= $H$2,"Y","N"))
H42: =IF(OR(F42="",G42=""),"", (G42-F42)*1440) | I42: =IF(H42="","",IF(H42<= $H$2,"Y","N"))
H43: =IF(OR(F43="",G43=""),"", (G43-F43)*1440) | I43: =IF(H43="","",IF(H43<= $H$2,"Y","N"))
H44: =IF(OR(F44="",G44=""),"", (G44-F44)*1440) | I44: =IF(H44="","",IF(H44<= $H$2,"Y","N"))
H45: =IF(OR(F45="",G45=""),"", (G45-F45)*1440) | I45: =IF(H45="","",IF(H45<= $H$2,"Y","N"))
... H100: =IF(OR(F100="",G100=""),"", (G100-F100)*1440) | I100: =IF(H100="","",IF(H100<= $H$2,"Y","N"))

Sheet CREW_LOG
A1: Date | B1: Shift | C1: Line | D1: Employee | E1: Position | F1: Machine (schedule) | G1: Downtime Area (events) | H1: Present (Y/N) | I1: Notes | J1: Area DT (min) | K1: Availability % | L1: Line OEE | M1: Machine Score | N1: Grade | O1: OT Labor
A2: =PASSDOWN!B2 -> 46078 | B2: =PASSDOWN!E2 -> 3rd | C2: 1 | D2: Reuben Callamco | E2: Checker | F2: Checker | H2: Y | J2: =IF(OR(A2="",B2="",C2="",G2=""),"",SUMIFS(EVENTS!$G$5:$G$204,EVENTS!$A$5:$A$204,A2,EVENTS!$B$5:$B$204,B2,EVENTS!$C$5:$C$204,C2,EVENTS!$H$5:$H$204,G2)) | K2: =IF(J2="","",MAX(0,1-J2/IF(PASSDOWN!$U$2="",720,PASSDOWN!$U$2))) | L2: =IFERROR(INDEX(PASSDOWN!$G$11:$G$15,MATCH(C2,PASSDOWN!$A$11:$A$15,0)),"") -> 0 | M2: =IF(OR(K2="",L2=""),"",ROUND(100*K2*IF(L2>1,L2/100,L2),0)) | N2: =IF(M2="","",IF(M2>=90,"A",IF(M2>=80,"B",IF(M2>=70,"C",IF(M2>=60,"D","F"))))) | O2: N | W2: CREW ROSTER BY LINE (from Staffing → Crew Log)
A3: =PASSDOWN!B2 -> 46078 | B3: =PASSDOWN!E2 -> 3rd | C3: 1 | D3: Maria Balzcar | E3: Labeler | F3: Labeler | H3: Y | J3: =IF(OR(A3="",B3="",C3="",G3=""),"",SUMIFS(EVENTS!$G$5:$G$204,EVENTS!$A$5:$A$204,A3,EVENTS!$B$5:$B$204,B3,EVENTS!$C$5:$C$204,C3,EVENTS!$H$5:$H$204,G3)) | K3: =IF(J3="","",MAX(0,1-J3/IF(PASSDOWN!$U$2="",720,PASSDOWN!$U$2))) | L3: =IFERROR(INDEX(PASSDOWN!$G$11:$G$15,MATCH(C3,PASSDOWN!$A$11:$A$15,0)),"") -> 0 | M3: =IF(OR(K3="",L3=""),"",ROUND(100*K3*IF(L3>1,L3/100,L3),0)) | N3: =IF(M3="","",IF(M3>=90,"A",IF(M3>=80,"B",IF(M3>=70,"C",IF(M3>=60,"D","F"))))) | O3: N | W3: Total Crew | X3: =COUNTA(CREW_LOG!D2:D53) -> 52 | Y3: Present | Z3: =COUNTIF(CREW_LOG!H2:H53,"Y") -> 51 | AA3: Absent | AB3: =COUNTIF(CREW_LOG!H2:H53,"N") -> 0 | AC3: OT Labor | AD3: =COUNTIF(CREW_LOG!O2:O53,"Y") -> 18
A4: =PASSDOWN!B2 -> 46078 | B4: =PASSDOWN!E2 -> 3rd | C4: 1 | D4: Alan | E4: Caser | F4: Caser | H4: Y | J4: =IF(OR(A4="",B4="",C4="",G4=""),"",SUMIFS(EVENTS!$G$5:$G$204,EVENTS!$A$5:$A$204,A4,EVENTS!$B$5:$B$204,B4,EVENTS!$C$5:$C$204,C4,EVENTS!$H$5:$H$204,G4)) | K4: =IF(J4="","",MAX(0,1-J4/IF(PASSDOWN!$U$2="",720,PASSDOWN!$U$2))) | L4: =IFERROR(INDEX(PASSDOWN!$G$11:$G$15,MATCH(C4,PASSDOWN!$A$11:$A$15,0)),"") -> 0 | M4: =IF(OR(K4="",L4=""),"",ROUND(100*K4*IF(L4>1,L4/100,L4),0)) | N4: =IF(M4="","",IF(M4>=90,"A",IF(M4>=80,"B",IF(M4>=70,"C",IF(M4>=60,"D","F"))))) | O4: Y
A5: =PASSDOWN!B2 -> 46078 | B5: =PASSDOWN!E2 -> 3rd | C5: 1 | D5: Angelica Munoz | E5: Shrink Tunnel | F5: Shrink Tunnel | H5: Y | J5: =IF(OR(A5="",B5="",C5="",G5=""),"",SUMIFS(EVENTS!$G$5:$G$204,EVENTS!$A$5:$A$204,A5,EVENTS!$B$5:$B$204,B5,EVENTS!$C$5:$C$204,C5,EVENTS!$H$5:$H$204,G5)) | K5: =IF(J5="","",MAX(0,1-J5/IF(PASSDOWN!$U$2="",720,PASSDOWN!$U$2))) | L5: =IFERROR(INDEX(PASSDOWN!$G$11:$G$15,MATCH(C5,PASSDOWN!$A$11:$A$15,0)),"") -> 0 | M5: =IF(OR(K5="",L5=""),"",ROUND(100*K5*IF(L5>1,L5/100,L5),0)) | N5: =IF(M5="","",IF(M5>=90,"A",IF(M5>=80,"B",IF(M5>=70,"C",IF(M5>=60,"D","F"))))) | O5: N | W5: Line | X5: Pri | Y5: Employee | Z5: Position | AA5: OT? | AB5: Present | AC5: Notes
A6: =PASSDOWN!B2 -> 46078 | B6: =PASSDOWN!E2 -> 3rd | C6: 1 | D6: Maria Graciano | E6: Palletizer | F6: Palletizer | H6: Y | J6: =IF(OR(A6="",B6="",C6="",G6=""),"",SUMIFS(EVENTS!$G$5:$G$204,EVENTS!$A$5:$A$204,A6,EVENTS!$B$5:$B$204,B6,EVENTS!$C$5:$C$204,C6,EVENTS!$H$5:$H$204,G6)) | K6: =IF(J6="","",MAX(0,1-J6/IF(PASSDOWN!$U$2="",720,PASSDOWN!$U$2))) | L6: =IFERROR(INDEX(PASSDOWN!$G$11:$G$15,MATCH(C6,PASSDOWN!$A$11:$A$15,0)),"") -> 0 | M6: =IF(OR(K6="",L6=""),"",ROUND(100*K6*IF(L6>1,L6/100,L6),0)) | N6: =IF(M6="","",IF(M6>=90,"A",IF(M6>=80,"B",IF(M6>=70,"C",IF(M6>=60,"D","F"))))) | O6: N | W6: =CREW_LOG!C2 -> 1 | X6: =IFERROR(INDEX(#REF!,MATCH(CREW_LOG!C2,#REF!,0)),"") | Y6: =CREW_LOG!D2 -> Reuben Callamco | Z6: =CREW_LOG!E2 -> Checker | AA6: =CREW_LOG!O2 -> N | AB6: =CREW_LOG!H2 -> Y | AC6: =CREW_LOG!I2 -> 0
A7: =PASSDOWN!B2 -> 46078 | B7: =PASSDOWN!E2 -> 3rd | C7: 1 | D7: Daniel Orozco Ramos | E7: Ryson Spiral | L7: =IFERROR(INDEX(PASSDOWN!$G$11:$G$15,MATCH(C7,PASSDOWN!$A$11:$A$15,0)),"") -> 0 | O7: Y | W7: =CREW_LOG!C3 -> 1 | X7: =IFERROR(INDEX(#REF!,MATCH(CREW_LOG!C3,#REF!,0)),"") | Y7: =CREW_LOG!D3 -> Maria Balzcar | Z7: =CREW_LOG!E3 -> Labeler | AA7: =CREW_LOG!O3 -> N | AB7: =CREW_LOG!H3 -> Y | AC7: =CREW_LOG!I3 -> 0
A8: =PASSDOWN!B2 -> 46078 | B8: =PASSDOWN!E2 -> 3rd | C8: 1 | D8: Rodrigo Hernandez | E8: Drive Off | F8: Drive Off | H8: Y | J8: =IF(OR(A8="",B8="",C8="",G8=""),"",SUMIFS(EVENTS!$G$5:$G$204,EVENTS!$A$5:$A$204,A8,EVENTS!$B$5:$B$204,B8,EVENTS!$C$5:$C$204,C8,EVENTS!$H$5:$H$204,G8)) | K8: =IF(J8="","",MAX(0,1-J8/IF(PASSDOWN!$U$2="",720,PASSDOWN!$U$2))) | L8: =IFERROR(INDEX(PASSDOWN!$G$11:$G$15,MATCH(C8,PASSDOWN!$A$11:$A$15,0)),"") -> 0 | M8: =IF(OR(K8="",L8=""),"",ROUND(100*K8*IF(L8>1,L8/100,L8),0)) | N8: =IF(M8="","",IF(M8>=90,"A",IF(M8>=80,"B",IF(M8>=70,"C",IF(M8>=60,"D","F"))))) | O8: N | W8: =CREW_LOG!C4 -> 1 | X8: =IFERROR(INDEX(#REF!,MATCH(CREW_LOG!C4,#REF!,0)),"") | Y8: =CREW_LOG!D4 -> Alan | Z8: =CREW_LOG!E4 -> Caser | AA8: =CREW_LOG!O4 -> Y | AB8: =CREW_LOG!H4 -> Y | AC8: =CREW_LOG!I4 -> 0
A9: =PASSDOWN!B2 -> 46078 | B9: =PASSDOWN!E2 -> 3rd | C9: 1 | D9: Fernando Rocha | E9: Releif Operator | F9: Releif Operator | H9: Y | J9: =IF(OR(A9="",B9="",C9="",G9=""),"",SUMIFS(EVENTS!$G$5:$G$204,EVENTS!$A$5:$A$204,A9,EVENTS!$B$5:$B$204,B9,EVENTS!$C$5:$C$204,C9,EVENTS!$H$5:$H$204,G9)) | K9: =IF(J9="","",MAX(0,1-J9/IF(PASSDOWN!$U$2="",720,PASSDOWN!$U$2))) | L9: =IFERROR(INDEX(PASSDOWN!$G$11:$G$15,MATCH(C9,PASSDOWN!$A$11:$A$15,0)),"") -> 0 | M9: =IF(OR(K9="",L9=""),"",ROUND(100*K9*IF(L9>1,L9/100,L9),0)) | N9: =IF(M9="","",IF(M9>=90,"A",IF(M9>=80,"B",IF(M9>=70,"C",IF(M9>=60,"D","F"))))) | O9: N | W9: =CREW_LOG!C5 -> 1 | X9: =IFERROR(INDEX(#REF!,MATCH(CREW_LOG!C5,#REF!,0)),"") | Y9: =CREW_LOG!D5 -> Angelica Munoz | Z9: =CREW_LOG!E5 -> Shrink Tunnel | AA9: =CREW_LOG!O5 -> N | AB9: =CREW_LOG!H5 -> Y | AC9: =CREW_LOG!I5 -> 0
A10: =PASSDOWN!B2 -> 46078 | B10: =PASSDOWN!E2 -> 3rd | C10: 2 | D10: Kenny Bryant | E10: Checker | F10: Checker | H10: Y | J10: =IF(OR(A10="",B10="",C10="",G10=""),"",SUMIFS(EVENTS!$G$5:$G$204,EVENTS!$A$5:$A$204,A10,EVENTS!$B$5:$B$204,B10,EVENTS!$C$5:$C$204,C10,EVENTS!$H$5:$H$204,G10)) | K10: =IF(J10="","",MAX(0,1-J10/IF(PASSDOWN!$U$2="",720,PASSDOWN!$U$2))) | L10: =IFERROR(INDEX(PASSDOWN!$G$11:$G$15,MATCH(C10,PASSDOWN!$A$11:$A$15,0)),"") -> 0 | M10: =IF(OR(K10="",L10=""),"",ROUND(100*K10*IF(L10>1,L10/100,L10),0)) | N10: =IF(M10="","",IF(M10>=90,"A",IF(M10>=80,"B",IF(M10>=70,"C",IF(M10>=60,"D","F"))))) | O10: N | W10: =CREW_LOG!C6 -> 1 | X10: =IFERROR(INDEX(#REF!,MATCH(CREW_LOG!C6,#REF!,0)),"") | Y10: =CREW_LOG!D6 -> Maria Graciano | Z10: =CREW_LOG!E6 -> Palletizer | AA10: =CREW_LOG!O6 -> N | AB10: =CREW_LOG!H6 -> Y | AC10: =CREW_LOG!I6 -> 0
A11: =PASSDOWN!B2 -> 46078 | B11: =PASSDOWN!E2 -> 3rd | C11: 2 | D11: Mayra Cacique | E11: Depal | F11: Depal | H11: Y | J11: =IF(OR(A11="",B11="",C11="",G11=""),"",SUMIFS(EVENTS!$G$5:$G$204,EVENTS!$A$5:$A$204,A11,EVENTS!$B$5:$B$204,B11,EVENTS!$C$5:$C$204,C11,EVENTS!$H$5:$H$204,G11)) | K11: =IF(J11="","",MAX(0,1-J11/IF(PASSDOWN!$U$2="",720,PASSDOWN!$U$2))) | L11: =IFERROR(INDEX(PASSDOWN!$G$11:$G$15,MATCH(C11,PASSDOWN!$A$11:$A$15,0)),"") -> 0 | M11: =IF(OR(K11="",L11=""),"",ROUND(100*K11*IF(L11>1,L11/100,L11),0)) | N11: =IF(M11="","",IF(M11>=90,"A",IF(M11>=80,"B",IF(M11>=70,"C",IF(M11>=60,"D","F"))))) | O11: N | W11: =CREW_LOG!C8 -> 1 | X11: =IFERROR(INDEX(#REF!,MATCH(CREW_LOG!C8,#REF!,0)),"") | Y11: =CREW_LOG!D8 -> Rodrigo Hernandez | Z11: =CREW_LOG!E8 -> Drive Off | AA11: =CREW_LOG!O8 -> N | AB11: =CREW_LOG!H8 -> Y | AC11: =CREW_LOG!I8 -> 0
A12: =PASSDOWN!B2 -> 46078 | B12: =PASSDOWN!E2 -> 3rd | C12: 2 | D12: Paola Garcia | E12: Labeler B | F12: Labeler B | H12: Y | J12: =IF(OR(A12="",B12="",C12="",G12=""),"",SUMIFS(EVENTS!$G$5:$G$204,EVENTS!$A$5:$A$204,A12,EVENTS!$B$5:$B$204,B12,EVENTS!$C$5:$C$204,C12,EVENTS!$H$5:$H$204,G12)) | K12: =IF(J12="","",MAX(0,1-J12/IF(PASSDOWN!$U$2="",720,PASSDOWN!$U$2))) | L12: =IFERROR(INDEX(PASSDOWN!$G$11:$G$15,MATCH(C12,PASSDOWN!$A$11:$A$15,0)),"") -> 0 | M12: =IF(OR(K12="",L12=""),"",ROUND(100*K12*IF(L12>1,L12/100,L12),0)) | N12: =IF(M12="","",IF(M12>=90,"A",IF(M12>=80,"B",IF(M12>=70,"C",IF(M12>=60,"D","F"))))) | O12: N | W12: =CREW_LOG!C9 -> 1 | X12: =IFERROR(INDEX(#REF!,MATCH(CREW_LOG!C9,#REF!,0)),"") | Y12: =CREW_LOG!D9 -> Fernando Rocha | Z12: =CREW_LOG!E9 -> Releif Operator | AA12: =CREW_LOG!O9 -> N | AB12: =CREW_LOG!H9 -> Y | AC12: =CREW_LOG!I9 -> 0
A13: =PASSDOWN!B2 -> 46078 | B13: =PASSDOWN!E2 -> 3rd | C13: 2 | D13: Rufino Arguellas | E13: Riverwood | F13: Riverwood | H13: Y | J13: =IF(OR(A13="",B13="",C13="",G13=""),"",SUMIFS(EVENTS!$G$5:$G$204,EVENTS!$A$5:$A$204,A13,EVENTS!$B$5:$B$204,B13,EVENTS!$C$5:$C$204,C13,EVENTS!$H$5:$H$204,G13)) | K13: =IF(J13="","",MAX(0,1-J13/IF(PASSDOWN!$U$2="",720,PASSDOWN!$U$2))) | L13: =IFERROR(INDEX(PASSDOWN!$G$11:$G$15,MATCH(C13,PASSDOWN!$A$11:$A$15,0)),"") -> 0 | M13: =IF(OR(K13="",L13=""),"",ROUND(100*K13*IF(L13>1,L13/100,L13),0)) | N13: =IF(M13="","",IF(M13>=90,"A",IF(M13>=80,"B",IF(M13>=70,"C",IF(M13>=60,"D","F"))))) | O13: N | W13: =CREW_LOG!C10 -> 2 | X13: =IFERROR(INDEX(#REF!,MATCH(CREW_LOG!C10,#REF!,0)),"") | Y13: =CREW_LOG!D10 -> Kenny Bryant | Z13: =CREW_LOG!E10 -> Checker | AA13: =CREW_LOG!O10 -> N | AB13: =CREW_LOG!H10 -> Y | AC13: =CREW_LOG!I10 -> 0
A14: =PASSDOWN!B2 -> 46078 | B14: =PASSDOWN!E2 -> 3rd | C14: 2 | D14: Ramero Ramirez | E14: Upstairs | F14: Upstairs | H14: Y | J14: =IF(OR(A14="",B14="",C14="",G14=""),"",SUMIFS(EVENTS!$G$5:$G$204,EVENTS!$A$5:$A$204,A14,EVENTS!$B$5:$B$204,B14,EVENTS!$C$5:$C$204,C14,EVENTS!$H$5:$H$204,G14)) | K14: =IF(J14="","",MAX(0,1-J14/IF(PASSDOWN!$U$2="",720,PASSDOWN!$U$2))) | L14: =IFERROR(INDEX(PASSDOWN!$G$11:$G$15,MATCH(C14,PASSDOWN!$A$11:$A$15,0)),"") -> 0 | M14: =IF(OR(K14="",L14=""),"",ROUND(100*K14*IF(L14>1,L14/100,L14),0)) | N14: =IF(M14="","",IF(M14>=90,"A",IF(M14>=80,"B",IF(M14>=70,"C",IF(M14>=60,"D","F"))))) | O14: N | W14: =CREW_LOG!C11 -> 2 | X14: =IFERROR(INDEX(#REF!,MATCH(CREW_LOG!C11,#REF!,0)),"") | Y14: =CREW_LOG!D11 -> Mayra Cacique | Z14: =CREW_LOG!E11 -> Depal | AA14: =CREW_LOG!O11 -> N | AB14: =CREW_LOG!H11 -> Y | AC14: =CREW_LOG!I11 -> 0
A15: =PASSDOWN!B2 -> 46078 | B15: =PASSDOWN!E2 -> 3rd | C15: 2 | D15: Maria Espinoza | E15: Palletizer | F15: Palletizer | H15: Y | J15: =IF(OR(A15="",B15="",C15="",G15=""),"",SUMIFS(EVENTS!$G$5:$G$204,EVENTS!$A$5:$A$204,A15,EVENTS!$B$5:$B$204,B15,EVENTS!$C$5:$C$204,C15,EVENTS!$H$5:$H$204,G15)) | K15: =IF(J15="","",MAX(0,1-J15/IF(PASSDOWN!$U$2="",720,PASSDOWN!$U$2))) | L15: =IFERROR(INDEX(PASSDOWN!$G$11:$G$15,MATCH(C15,PASSDOWN!$A$11:$A$15,0)),"") -> 0 | M15: =IF(OR(K15="",L15=""),"",ROUND(100*K15*IF(L15>1,L15/100,L15),0)) | N15: =IF(M15="","",IF(M15>=90,"A",IF(M15>=80,"B",IF(M15>=70,"C",IF(M15>=60,"D","F"))))) | O15: N | W15: =CREW_LOG!C12 -> 2 | X15: =IFERROR(INDEX(#REF!,MATCH(CREW_LOG!C12,#REF!,0)),"") | Y15: =CREW_LOG!D12 -> Paola Garcia | Z15: =CREW_LOG!E12 -> Labeler B | AA15: =CREW_LOG!O12 -> N | AB15: =CREW_LOG!H12 -> Y | AC15: =CREW_LOG!I12 -> 0
A16: =PASSDOWN!B2 -> 46078 | B16: =PASSDOWN!E2 -> 3rd | C16: 2 | D16: Don Gibson | E16: Drive Off | F16: Drive Off | H16: Y | J16: =IF(OR(A16="",B16="",C16="",G16=""),"",SUMIFS(EVENTS!$G$5:$G$204,EVENTS!$A$5:$A$204,A16,EVENTS!$B$5:$B$204,B16,EVENTS!$C$5:$C$204,C16,EVENTS!$H$5:$H$204,G16)) | K16: =IF(J16="","",MAX(0,1-J16/IF(PASSDOWN!$U$2="",720,PASSDOWN!$U$2))) | L16: =IFERROR(INDEX(PASSDOWN!$G$11:$G$15,MATCH(C16,PASSDOWN!$A$11:$A$15,0)),"") -> 0 | M16: =IF(OR(K16="",L16=""),"",ROUND(100*K16*IF(L16>1,L16/100,L16),0)) | N16: =IF(M16="","",IF(M16>=90,"A",IF(M16>=80,"B",IF(M16>=70,"C",IF(M16>=60,"D","F"))))) | O16: N | W16: =CREW_LOG!C13 -> 2 | X16: =IFERROR(INDEX(#REF!,MATCH(CREW_LOG!C13,#REF!,0)),"") | Y16: =CREW_LOG!D13 -> Rufino Arguellas | Z16: =CREW_LOG!E13 -> Riverwood | AA16: =CREW_LOG!O13 -> N | AB16: =CREW_LOG!H13 -> Y | AC16: =CREW_LOG!I13 -> 0
A17: =PASSDOWN!B2 -> 46078 | B17: =PASSDOWN!E2 -> 3rd | C17: 2 | D17: Cristian Garcia | E17: Releif Operator | F17: Releif Operator | H17: Y | J17: =IF(OR(A17="",B17="",C17="",G17=""),"",SUMIFS(EVENTS!$G$5:$G$204,EVENTS!$A$5:$A$204,A17,EVENTS!$B$5:$B$204,B17,EVENTS!$C$5:$C$204,C17,EVENTS!$H$5:$H$204,G17)) | K17: =IF(J17="","",MAX(0,1-J17/IF(PASSDOWN!$U$2="",720,PASSDOWN!$U$2))) | L17: =IFERROR(INDEX(PASSDOWN!$G$11:$G$15,MATCH(C17,PASSDOWN!$A$11:$A$15,0)),"") -> 0 | M17: =IF(OR(K17="",L17=""),"",ROUND(100*K17*IF(L17>1,L17/100,L17),0)) | N17: =IF(M17="","",IF(M17>=90,"A",IF(M17>=80,"B",IF(M17>=70,"C",IF(M17>=60,"D","F"))))) | O17: N | W17: =CREW_LOG!C14 -> 2 | X17: =IFERROR(INDEX(#REF!,MATCH(CREW_LOG!C14,#REF!,0)),"") | Y17: =CREW_LOG!D14 -> Ramero Ramirez | Z17: =CREW_LOG!E14 -> Upstairs | AA17: =CREW_LOG!O14 -> N | AB17: =CREW_LOG!H14 -> Y | AC17: =CREW_LOG!I14 -> 0
A18: =PASSDOWN!B2 -> 46078 | B18: =PASSDOWN!E2 -> 3rd | C18: 2 | D18: Maria Hermosilla | E18: RO Training | F18: RO Training | H18: Y | J18: =IF(OR(A18="",B18="",C18="",G18=""),"",SUMIFS(EVENTS!$G$5:$G$204,EVENTS!$A$5:$A$204,A18,EVENTS!$B$5:$B$204,B18,EVENTS!$C$5:$C$204,C18,EVENTS!$H$5:$H$204,G18)) | K18: =IF(J18="","",MAX(0,1-J18/IF(PASSDOWN!$U$2="",720,PASSDOWN!$U$2))) | L18: =IFERROR(INDEX(PASSDOWN!$G$11:$G$15,MATCH(C18,PASSDOWN!$A$11:$A$15,0)),"") -> 0 | M18: =IF(OR(K18="",L18=""),"",ROUND(100*K18*IF(L18>1,L18/100,L18),0)) | N18: =IF(M18="","",IF(M18>=90,"A",IF(M18>=80,"B",IF(M18>=70,"C",IF(M18>=60,"D","F"))))) | O18: N | W18: =CREW_LOG!C15 -> 2 | X18: =IFERROR(INDEX(#REF!,MATCH(CREW_LOG!C15,#REF!,0)),"") | Y18: =CREW_LOG!D15 -> Maria Espinoza | Z18: =CREW_LOG!E15 -> Palletizer | AA18: =CREW_LOG!O15 -> N | AB18: =CREW_LOG!H15 -> Y | AC18: =CREW_LOG!I15 -> 0
A19: =PASSDOWN!B2 -> 46078 | B19: =PASSDOWN!E2 -> 3rd | C19: 3 | D19: Dan Martinez | E19: Checker | F19: Checker | H19: Y | J19: =IF(OR(A19="",B19="",C19="",G19=""),"",SUMIFS(EVENTS!$G$5:$G$204,EVENTS!$A$5:$A$204,A19,EVENTS!$B$5:$B$204,B19,EVENTS!$C$5:$C$204,C19,EVENTS!$H$5:$H$204,G19)) | K19: =IF(J19="","",MAX(0,1-J19/IF(PASSDOWN!$U$2="",720,PASSDOWN!$U$2))) | L19: =IFERROR(INDEX(PASSDOWN!$G$11:$G$15,MATCH(C19,PASSDOWN!$A$11:$A$15,0)),"") -> 0 | M19: =IF(OR(K19="",L19=""),"",ROUND(100*K19*IF(L19>1,L19/100,L19),0)) | N19: =IF(M19="","",IF(M19>=90,"A",IF(M19>=80,"B",IF(M19>=70,"C",IF(M19>=60,"D","F"))))) | O19: N | W19: =CREW_LOG!C16 -> 2 | X19: =IFERROR(INDEX(#REF!,MATCH(CREW_LOG!C16,#REF!,0)),"") | Y19: =CREW_LOG!D16 -> Don Gibson | Z19: =CREW_LOG!E16 -> Drive Off | AA19: =CREW_LOG!O16 -> N | AB19: =CREW_LOG!H16 -> Y | AC19: =CREW_LOG!I16 -> 0
A20: =PASSDOWN!B2 -> 46078 | B20: =PASSDOWN!E2 -> 3rd | C20: 3 | D20: Netafil Belmonte | E20: Depal | F20: Depal | H20: Y | J20: =IF(OR(A20="",B20="",C20="",G20=""),"",SUMIFS(EVENTS!$G$5:$G$204,EVENTS!$A$5:$A$204,A20,EVENTS!$B$5:$B$204,B20,EVENTS!$C$5:$C$204,C20,EVENTS!$H$5:$H$204,G20)) | K20: =IF(J20="","",MAX(0,1-J20/IF(PASSDOWN!$U$2="",720,PASSDOWN!$U$2))) | L20: =IFERROR(INDEX(PASSDOWN!$G$11:$G$15,MATCH(C20,PASSDOWN!$A$11:$A$15,0)),"") -> 0 | M20: =IF(OR(K20="",L20=""),"",ROUND(100*K20*IF(L20>1,L20/100,L20),0)) | N20: =IF(M20="","",IF(M20>=90,"A",IF(M20>=80,"B",IF(M20>=70,"C",IF(M20>=60,"D","F"))))) | O20: N | W20: =CREW_LOG!C17 -> 2 | X20: =IFERROR(INDEX(#REF!,MATCH(CREW_LOG!C17,#REF!,0)),"") | Y20: =CREW_LOG!D17 -> Cristian Garcia | Z20: =CREW_LOG!E17 -> Releif Operator | AA20: =CREW_LOG!O17 -> N | AB20: =CREW_LOG!H17 -> Y | AC20: =CREW_LOG!I17 -> 0
A21: =PASSDOWN!B2 -> 46078 | B21: =PASSDOWN!E2 -> 3rd | C21: 3 | D21: Melesio Velazco | E21: Labeler | F21: Labeler | H21: Y | J21: =IF(OR(A21="",B21="",C21="",G21=""),"",SUMIFS(EVENTS!$G$5:$G$204,EVENTS!$A$5:$A$204,A21,EVENTS!$B$5:$B$204,B21,EVENTS!$C$5:$C$204,C21,EVENTS!$H$5:$H$204,G21)) | K21: =IF(J21="","",MAX(0,1-J21/IF(PASSDOWN!$U$2="",720,PASSDOWN!$U$2))) | L21: =IFERROR(INDEX(PASSDOWN!$G$11:$G$15,MATCH(C21,PASSDOWN!$A$11:$A$15,0)),"") -> 0 | M21: =IF(OR(K21="",L21=""),"",ROUND(100*K21*IF(L21>1,L21/100,L21),0)) | N21: =IF(M21="","",IF(M21>=90,"A",IF(M21>=80,"B",IF(M21>=70,"C",IF(M21>=60,"D","F"))))) | O21: N | W21: =CREW_LOG!C18 -> 2 | X21: =IFERROR(INDEX(#REF!,MATCH(CREW_LOG!C18,#REF!,0)),"") | Y21: =CREW_LOG!D18 -> Maria Hermosilla | Z21: =CREW_LOG!E18 -> RO Training | AA21: =CREW_LOG!O18 -> N | AB21: =CREW_LOG!H18 -> Y | AC21: =CREW_LOG!I18 -> 0
A22: =PASSDOWN!B2 -> 46078 | B22: =PASSDOWN!E2 -> 3rd | C22: 3 | D22: Maria Gonzalez | E22: Caser | F22: Caser | H22: Y | J22: =IF(OR(A22="",B22="",C22="",G22=""),"",SUMIFS(EVENTS!$G$5:$G$204,EVENTS!$A$5:$A$204,A22,EVENTS!$B$5:$B$204,B22,EVENTS!$C$5:$C$204,C22,EVENTS!$H$5:$H$204,G22)) | K22: =IF(J22="","",MAX(0,1-J22/IF(PASSDOWN!$U$2="",720,PASSDOWN!$U$2))) | L22: =IFERROR(INDEX(PASSDOWN!$G$11:$G$15,MATCH(C22,PASSDOWN!$A$11:$A$15,0)),"") -> 0 | M22: =IF(OR(K22="",L22=""),"",ROUND(100*K22*IF(L22>1,L22/100,L22),0)) | N22: =IF(M22="","",IF(M22>=90,"A",IF(M22>=80,"B",IF(M22>=70,"C",IF(M22>=60,"D","F"))))) | O22: N | W22: =CREW_LOG!C26 -> 4 | X22: =IFERROR(INDEX(#REF!,MATCH(CREW_LOG!C26,#REF!,0)),"") | Y22: =CREW_LOG!D26 -> Brayan Rocha | Z22: =CREW_LOG!E26 -> Checker | AA22: =CREW_LOG!O26 -> N | AB22: =CREW_LOG!H26 -> Y | AC22: =CREW_LOG!I26 -> 0
A23: =PASSDOWN!B2 -> 46078 | B23: =PASSDOWN!E2 -> 3rd | C23: 3 | D23: Lorena Velasco | E23: Shrink Tunnel | F23: Shrink Tunnel | H23: Y | J23: =IF(OR(A23="",B23="",C23="",G23=""),"",SUMIFS(EVENTS!$G$5:$G$204,EVENTS!$A$5:$A$204,A23,EVENTS!$B$5:$B$204,B23,EVENTS!$C$5:$C$204,C23,EVENTS!$H$5:$H$204,G23)) | K23: =IF(J23="","",MAX(0,1-J23/IF(PASSDOWN!$U$2="",720,PASSDOWN!$U$2))) | L23: =IFERROR(INDEX(PASSDOWN!$G$11:$G$15,MATCH(C23,PASSDOWN!$A$11:$A$15,0)),"") -> 0 | M23: =IF(OR(K23="",L23=""),"",ROUND(100*K23*IF(L23>1,L23/100,L23),0)) | N23: =IF(M23="","",IF(M23>=90,"A",IF(M23>=80,"B",IF(M23>=70,"C",IF(M23>=60,"D","F"))))) | O23: N | W23: =CREW_LOG!C27 -> 4 | X23: =IFERROR(INDEX(#REF!,MATCH(CREW_LOG!C27,#REF!,0)),"") | Y23: =CREW_LOG!D27 -> Clara Velazco | Z23: =CREW_LOG!E27 -> Depal: | AA23: =CREW_LOG!O27 -> N | AB23: =CREW_LOG!H27 -> Y | AC23: =CREW_LOG!I27 -> 0
A24: =PASSDOWN!B2 -> 46078 | B24: =PASSDOWN!E2 -> 3rd | C24: 3 | D24: Minerva Garza | E24: Palletizer | F24: Palletizer | H24: Y | J24: =IF(OR(A24="",B24="",C24="",G24=""),"",SUMIFS(EVENTS!$G$5:$G$204,EVENTS!$A$5:$A$204,A24,EVENTS!$B$5:$B$204,B24,EVENTS!$C$5:$C$204,C24,EVENTS!$H$5:$H$204,G24)) | K24: =IF(J24="","",MAX(0,1-J24/IF(PASSDOWN!$U$2="",720,PASSDOWN!$U$2))) | L24: =IFERROR(INDEX(PASSDOWN!$G$11:$G$15,MATCH(C24,PASSDOWN!$A$11:$A$15,0)),"") -> 0 | M24: =IF(OR(K24="",L24=""),"",ROUND(100*K24*IF(L24>1,L24/100,L24),0)) | N24: =IF(M24="","",IF(M24>=90,"A",IF(M24>=80,"B",IF(M24>=70,"C",IF(M24>=60,"D","F"))))) | O24: N | W24: =CREW_LOG!C28 -> 4 | X24: =IFERROR(INDEX(#REF!,MATCH(CREW_LOG!C28,#REF!,0)),"") | Y24: =CREW_LOG!D28 -> Irma Sandoval | Z24: =CREW_LOG!E28 -> Labeler | AA24: =CREW_LOG!O28 -> N | AB24: =CREW_LOG!H28 -> Y | AC24: =CREW_LOG!I28 -> 0
A25: =PASSDOWN!B2 -> 46078 | B25: =PASSDOWN!E2 -> 3rd | C25: 3 | D25: Ulises Moreno | E25: Drive Off | F25: Drive Off | H25: Y | J25: =IF(OR(A25="",B25="",C25="",G25=""),"",SUMIFS(EVENTS!$G$5:$G$204,EVENTS!$A$5:$A$204,A25,EVENTS!$B$5:$B$204,B25,EVENTS!$C$5:$C$204,C25,EVENTS!$H$5:$H$204,G25)) | K25: =IF(J25="","",MAX(0,1-J25/IF(PASSDOWN!$U$2="",720,PASSDOWN!$U$2))) | L25: =IFERROR(INDEX(PASSDOWN!$G$11:$G$15,MATCH(C25,PASSDOWN!$A$11:$A$15,0)),"") -> 0 | M25: =IF(OR(K25="",L25=""),"",ROUND(100*K25*IF(L25>1,L25/100,L25),0)) | N25: =IF(M25="","",IF(M25>=90,"A",IF(M25>=80,"B",IF(M25>=70,"C",IF(M25>=60,"D","F"))))) | O25: N | W25: =CREW_LOG!C29 -> 4 | X25: =IFERROR(INDEX(#REF!,MATCH(CREW_LOG!C29,#REF!,0)),"") | Y25: =CREW_LOG!D29 -> Rosa Haro Moreno | Z25: =CREW_LOG!E29 -> RA Jones | AA25: =CREW_LOG!O29 -> N | AB25: =CREW_LOG!H29 -> Y | AC25: =CREW_LOG!I29 -> 0
A26: =PASSDOWN!B2 -> 46078 | B26: =PASSDOWN!E2 -> 3rd | C26: 4 | D26: Brayan Rocha | E26: Checker | F26: Checker | H26: Y | J26: =IF(OR(A26="",B26="",C26="",G26=""),"",SUMIFS(EVENTS!$G$5:$G$204,EVENTS!$A$5:$A$204,A26,EVENTS!$B$5:$B$204,B26,EVENTS!$C$5:$C$204,C26,EVENTS!$H$5:$H$204,G26)) | K26: =IF(J26="","",MAX(0,1-J26/IF(PASSDOWN!$U$2="",720,PASSDOWN!$U$2))) | L26: =IFERROR(INDEX(PASSDOWN!$G$11:$G$15,MATCH(C26,PASSDOWN!$A$11:$A$15,0)),"") -> 0 | M26: =IF(OR(K26="",L26=""),"",ROUND(100*K26*IF(L26>1,L26/100,L26),0)) | N26: =IF(M26="","",IF(M26>=90,"A",IF(M26>=80,"B",IF(M26>=70,"C",IF(M26>=60,"D","F"))))) | O26: N | W26: =CREW_LOG!C30 -> 4 | X26: =IFERROR(INDEX(#REF!,MATCH(CREW_LOG!C30,#REF!,0)),"") | Y26: =CREW_LOG!D30 -> Milidia Dupairion | Z26: =CREW_LOG!E30 -> Traypacker | AA26: =CREW_LOG!O30 -> N | AB26: =CREW_LOG!H30 -> Y | AC26: =CREW_LOG!I30 -> 0
A27: =PASSDOWN!B2 -> 46078 | B27: =PASSDOWN!E2 -> 3rd | C27: 4 | D27: Clara Velazco | E27: Depal: | F27: Depal: | H27: Y | J27: =IF(OR(A27="",B27="",C27="",G27=""),"",SUMIFS(EVENTS!$G$5:$G$204,EVENTS!$A$5:$A$204,A27,EVENTS!$B$5:$B$204,B27,EVENTS!$C$5:$C$204,C27,EVENTS!$H$5:$H$204,G27)) | K27: =IF(J27="","",MAX(0,1-J27/IF(PASSDOWN!$U$2="",720,PASSDOWN!$U$2))) | L27: =IFERROR(INDEX(PASSDOWN!$G$11:$G$15,MATCH(C27,PASSDOWN!$A$11:$A$15,0)),"") -> 0 | M27: =IF(OR(K27="",L27=""),"",ROUND(100*K27*IF(L27>1,L27/100,L27),0)) | N27: =IF(M27="","",IF(M27>=90,"A",IF(M27>=80,"B",IF(M27>=70,"C",IF(M27>=60,"D","F"))))) | O27: N | W27: =CREW_LOG!C31 -> 4 | X27: =IFERROR(INDEX(#REF!,MATCH(CREW_LOG!C31,#REF!,0)),"") | Y27: =CREW_LOG!D31 -> Fiorella Belfiore | Z27: =CREW_LOG!E31 -> Palletizer | AA27: =CREW_LOG!O31 -> N | AB27: =CREW_LOG!H31 -> Y | AC27: =CREW_LOG!I31 -> 0
A28: =PASSDOWN!B2 -> 46078 | B28: =PASSDOWN!E2 -> 3rd | C28: 4 | D28: Irma Sandoval | E28: Labeler | F28: Labeler | H28: Y | J28: =IF(OR(A28="",B28="",C28="",G28=""),"",SUMIFS(EVENTS!$G$5:$G$204,EVENTS!$A$5:$A$204,A28,EVENTS!$B$5:$B$204,B28,EVENTS!$C$5:$C$204,C28,EVENTS!$H$5:$H$204,G28)) | K28: =IF(J28="","",MAX(0,1-J28/IF(PASSDOWN!$U$2="",720,PASSDOWN!$U$2))) | L28: =IFERROR(INDEX(PASSDOWN!$G$11:$G$15,MATCH(C28,PASSDOWN!$A$11:$A$15,0)),"") -> 0 | M28: =IF(OR(K28="",L28=""),"",ROUND(100*K28*IF(L28>1,L28/100,L28),0)) | N28: =IF(M28="","",IF(M28>=90,"A",IF(M28>=80,"B",IF(M28>=70,"C",IF(M28>=60,"D","F"))))) | O28: N | W28: =CREW_LOG!C32 -> 4 | X28: =IFERROR(INDEX(#REF!,MATCH(CREW_LOG!C32,#REF!,0)),"") | Y28: =CREW_LOG!D32 -> Jesus Orozco | Z28: =CREW_LOG!E32 -> Drive Off | AA28: =CREW_LOG!O32 -> N | AB28: =CREW_LOG!H32 -> Y | AC28: =CREW_LOG!I32 -> 0
A29: =PASSDOWN!B2 -> 46078 | B29: =PASSDOWN!E2 -> 3rd | C29: 4 | D29: Rosa Haro Moreno | E29: RA Jones | F29: RA Jones | H29: Y | J29: =IF(OR(A29="",B29="",C29="",G29=""),"",SUMIFS(EVENTS!$G$5:$G$204,EVENTS!$A$5:$A$204,A29,EVENTS!$B$5:$B$204,B29,EVENTS!$C$5:$C$204,C29,EVENTS!$H$5:$H$204,G29)) | K29: =IF(J29="","",MAX(0,1-J29/IF(PASSDOWN!$U$2="",720,PASSDOWN!$U$2))) | L29: =IFERROR(INDEX(PASSDOWN!$G$11:$G$15,MATCH(C29,PASSDOWN!$A$11:$A$15,0)),"") -> 0 | M29: =IF(OR(K29="",L29=""),"",ROUND(100*K29*IF(L29>1,L29/100,L29),0)) | N29: =IF(M29="","",IF(M29>=90,"A",IF(M29>=80,"B",IF(M29>=70,"C",IF(M29>=60,"D","F"))))) | O29: N | W29: =CREW_LOG!C33 -> 4 | X29: =IFERROR(INDEX(#REF!,MATCH(CREW_LOG!C33,#REF!,0)),"") | Y29: =CREW_LOG!D33 -> Juan Cacique | Z29: =CREW_LOG!E33 -> Releif Operator | AA29: =CREW_LOG!O33 -> N | AB29: =CREW_LOG!H33 -> Y | AC29: =CREW_LOG!I33 -> 0
A30: =PASSDOWN!B2 -> 46078 | B30: =PASSDOWN!E2 -> 3rd | C30: 4 | D30: Milidia Dupairion | E30: Traypacker | F30: Traypacker | H30: Y | J30: =IF(OR(A30="",B30="",C30="",G30=""),"",SUMIFS(EVENTS!$G$5:$G$204,EVENTS!$A$5:$A$204,A30,EVENTS!$B$5:$B$204,B30,EVENTS!$C$5:$C$204,C30,EVENTS!$H$5:$H$204,G30)) | K30: =IF(J30="","",MAX(0,1-J30/IF(PASSDOWN!$U$2="",720,PASSDOWN!$U$2))) | L30: =IFERROR(INDEX(PASSDOWN!$G$11:$G$15,MATCH(C30,PASSDOWN!$A$11:$A$15,0)),"") -> 0 | M30: =IF(OR(K30="",L30=""),"",ROUND(100*K30*IF(L30>1,L30/100,L30),0)) | N30: =IF(M30="","",IF(M30>=90,"A",IF(M30>=80,"B",IF(M30>=70,"C",IF(M30>=60,"D","F"))))) | O30: N | W30: =CREW_LOG!C19 -> 3 | X30: =IFERROR(INDEX(#REF!,MATCH(CREW_LOG!C19,#REF!,0)),"") | Y30: =CREW_LOG!D19 -> Dan Martinez | Z30: =CREW_LOG!E19 -> Checker | AA30: =CREW_LOG!O19 -> N | AB30: =CREW_LOG!H19 -> Y | AC30: =CREW_LOG!I19 -> 0
A31: =PASSDOWN!B2 -> 46078 | B31: =PASSDOWN!E2 -> 3rd | C31: 4 | D31: Fiorella Belfiore | E31: Palletizer | F31: Palletizer | H31: Y | J31: =IF(OR(A31="",B31="",C31="",G31=""),"",SUMIFS(EVENTS!$G$5:$G$204,EVENTS!$A$5:$A$204,A31,EVENTS!$B$5:$B$204,B31,EVENTS!$C$5:$C$204,C31,EVENTS!$H$5:$H$204,G31)) | K31: =IF(J31="","",MAX(0,1-J31/IF(PASSDOWN!$U$2="",720,PASSDOWN!$U$2))) | L31: =IFERROR(INDEX(PASSDOWN!$G$11:$G$15,MATCH(C31,PASSDOWN!$A$11:$A$15,0)),"") -> 0 | M31: =IF(OR(K31="",L31=""),"",ROUND(100*K31*IF(L31>1,L31/100,L31),0)) | N31: =IF(M31="","",IF(M31>=90,"A",IF(M31>=80,"B",IF(M31>=70,"C",IF(M31>=60,"D","F"))))) | O31: N | W31: =CREW_LOG!C20 -> 3 | X31: =IFERROR(INDEX(#REF!,MATCH(CREW_LOG!C20,#REF!,0)),"") | Y31: =CREW_LOG!D20 -> Netafil Belmonte | Z31: =CREW_LOG!E20 -> Depal | AA31: =CREW_LOG!O20 -> N | AB31: =CREW_LOG!H20 -> Y | AC31: =CREW_LOG!I20 -> 0
A32: =PASSDOWN!B2 -> 46078 | B32: =PASSDOWN!E2 -> 3rd | C32: 4 | D32: Jesus Orozco | E32: Drive Off | F32: Drive Off | H32: Y | J32: =IF(OR(A32="",B32="",C32="",G32=""),"",SUMIFS(EVENTS!$G$5:$G$204,EVENTS!$A$5:$A$204,A32,EVENTS!$B$5:$B$204,B32,EVENTS!$C$5:$C$204,C32,EVENTS!$H$5:$H$204,G32)) | K32: =IF(J32="","",MAX(0,1-J32/IF(PASSDOWN!$U$2="",720,PASSDOWN!$U$2))) | L32: =IFERROR(INDEX(PASSDOWN!$G$11:$G$15,MATCH(C32,PASSDOWN!$A$11:$A$15,0)),"") -> 0 | M32: =IF(OR(K32="",L32=""),"",ROUND(100*K32*IF(L32>1,L32/100,L32),0)) | N32: =IF(M32="","",IF(M32>=90,"A",IF(M32>=80,"B",IF(M32>=70,"C",IF(M32>=60,"D","F"))))) | O32: N | W32: =CREW_LOG!C21 -> 3 | X32: =IFERROR(INDEX(#REF!,MATCH(CREW_LOG!C21,#REF!,0)),"") | Y32: =CREW_LOG!D21 -> Melesio Velazco | Z32: =CREW_LOG!E21 -> Labeler | AA32: =CREW_LOG!O21 -> N | AB32: =CREW_LOG!H21 -> Y | AC32: =CREW_LOG!I21 -> 0
A33: =PASSDOWN!B2 -> 46078 | B33: =PASSDOWN!E2 -> 3rd | C33: 4 | D33: Juan Cacique | E33: Releif Operator | F33: Releif Operator | H33: Y | J33: =IF(OR(A33="",B33="",C33="",G33=""),"",SUMIFS(EVENTS!$G$5:$G$204,EVENTS!$A$5:$A$204,A33,EVENTS!$B$5:$B$204,B33,EVENTS!$C$5:$C$204,C33,EVENTS!$H$5:$H$204,G33)) | K33: =IF(J33="","",MAX(0,1-J33/IF(PASSDOWN!$U$2="",720,PASSDOWN!$U$2))) | L33: =IFERROR(INDEX(PASSDOWN!$G$11:$G$15,MATCH(C33,PASSDOWN!$A$11:$A$15,0)),"") -> 0 | M33: =IF(OR(K33="",L33=""),"",ROUND(100*K33*IF(L33>1,L33/100,L33),0)) | N33: =IF(M33="","",IF(M33>=90,"A",IF(M33>=80,"B",IF(M33>=70,"C",IF(M33>=60,"D","F"))))) | O33: N | W33: =CREW_LOG!C22 -> 3 | X33: =IFERROR(INDEX(#REF!,MATCH(CREW_LOG!C22,#REF!,0)),"") | Y33: =CREW_LOG!D22 -> Maria Gonzalez | Z33: =CREW_LOG!E22 -> Caser | AA33: =CREW_LOG!O22 -> N | AB33: =CREW_LOG!H22 -> Y | AC33: =CREW_LOG!I22 -> 0
A34: =PASSDOWN!B2 -> 46078 | B34: =PASSDOWN!E2 -> 3rd | C34: 5 | D34: Arlene Martinez | E34: Checker | F34: Checker | H34: Y | J34: =IF(OR(A34="",B34="",C34="",G34=""),"",SUMIFS(EVENTS!$G$5:$G$204,EVENTS!$A$5:$A$204,A34,EVENTS!$B$5:$B$204,B34,EVENTS!$C$5:$C$204,C34,EVENTS!$H$5:$H$204,G34)) | K34: =IF(J34="","",MAX(0,1-J34/IF(PASSDOWN!$U$2="",720,PASSDOWN!$U$2))) | L34: =IFERROR(INDEX(PASSDOWN!$G$11:$G$15,MATCH(C34,PASSDOWN!$A$11:$A$15,0)),"") -> 0 | M34: =IF(OR(K34="",L34=""),"",ROUND(100*K34*IF(L34>1,L34/100,L34),0)) | N34: =IF(M34="","",IF(M34>=90,"A",IF(M34>=80,"B",IF(M34>=70,"C",IF(M34>=60,"D","F"))))) | O34: N | W34: =CREW_LOG!C23 -> 3 | X34: =IFERROR(INDEX(#REF!,MATCH(CREW_LOG!C23,#REF!,0)),"") | Y34: =CREW_LOG!D23 -> Lorena Velasco | Z34: =CREW_LOG!E23 -> Shrink Tunnel | AA34: =CREW_LOG!O23 -> N | AB34: =CREW_LOG!H23 -> Y | AC34: =CREW_LOG!I23 -> 0
A35: =PASSDOWN!B2 -> 46078 | B35: =PASSDOWN!E2 -> 3rd | C35: 5 | D35: Angelina Childtveep | E35: Labeler | F35: Labeler | H35: Y | J35: =IF(OR(A35="",B35="",C35="",G35=""),"",SUMIFS(EVENTS!$G$5:$G$204,EVENTS!$A$5:$A$204,A35,EVENTS!$B$5:$B$204,B35,EVENTS!$C$5:$C$204,C35,EVENTS!$H$5:$H$204,G35)) | K35: =IF(J35="","",MAX(0,1-J35/IF(PASSDOWN!$U$2="",720,PASSDOWN!$U$2))) | L35: =IFERROR(INDEX(PASSDOWN!$G$11:$G$15,MATCH(C35,PASSDOWN!$A$11:$A$15,0)),"") -> 0 | M35: =IF(OR(K35="",L35=""),"",ROUND(100*K35*IF(L35>1,L35/100,L35),0)) | N35: =IF(M35="","",IF(M35>=90,"A",IF(M35>=80,"B",IF(M35>=70,"C",IF(M35>=60,"D","F"))))) | O35: N | W35: =CREW_LOG!C24 -> 3 | X35: =IFERROR(INDEX(#REF!,MATCH(CREW_LOG!C24,#REF!,0)),"") | Y35: =CREW_LOG!D24 -> Minerva Garza | Z35: =CREW_LOG!E24 -> Palletizer | AA35: =CREW_LOG!O24 -> N | AB35: =CREW_LOG!H24 -> Y | AC35: =CREW_LOG!I24 -> 0
A36: =PASSDOWN!B2 -> 46078 | B36: =PASSDOWN!E2 -> 3rd | C36: 5 | D36: Adriana Dupairon | E36: Traypacker | F36: Traypacker | H36: Y | J36: =IF(OR(A36="",B36="",C36="",G36=""),"",SUMIFS(EVENTS!$G$5:$G$204,EVENTS!$A$5:$A$204,A36,EVENTS!$B$5:$B$204,B36,EVENTS!$C$5:$C$204,C36,EVENTS!$H$5:$H$204,G36)) | K36: =IF(J36="","",MAX(0,1-J36/IF(PASSDOWN!$U$2="",720,PASSDOWN!$U$2))) | L36: =IFERROR(INDEX(PASSDOWN!$G$11:$G$15,MATCH(C36,PASSDOWN!$A$11:$A$15,0)),"") -> 0 | M36: =IF(OR(K36="",L36=""),"",ROUND(100*K36*IF(L36>1,L36/100,L36),0)) | N36: =IF(M36="","",IF(M36>=90,"A",IF(M36>=80,"B",IF(M36>=70,"C",IF(M36>=60,"D","F"))))) | O36: N | W36: =CREW_LOG!C25 -> 3 | X36: =IFERROR(INDEX(#REF!,MATCH(CREW_LOG!C25,#REF!,0)),"") | Y36: =CREW_LOG!D25 -> Ulises Moreno | Z36: =CREW_LOG!E25 -> Drive Off | AA36: =CREW_LOG!O25 -> N | AB36: =CREW_LOG!H25 -> Y | AC36: =CREW_LOG!I25 -> 0
A37: =PASSDOWN!B2 -> 46078 | B37: =PASSDOWN!E2 -> 3rd | C37: 5 | D37: Vanessa Gonzalez | E37: Palletizer | F37: Palletizer | H37: Y | J37: =IF(OR(A37="",B37="",C37="",G37=""),"",SUMIFS(EVENTS!$G$5:$G$204,EVENTS!$A$5:$A$204,A37,EVENTS!$B$5:$B$204,B37,EVENTS!$C$5:$C$204,C37,EVENTS!$H$5:$H$204,G37)) | K37: =IF(J37="","",MAX(0,1-J37/IF(PASSDOWN!$U$2="",720,PASSDOWN!$U$2))) | L37: =IFERROR(INDEX(PASSDOWN!$G$11:$G$15,MATCH(C37,PASSDOWN!$A$11:$A$15,0)),"") -> 0 | M37: =IF(OR(K37="",L37=""),"",ROUND(100*K37*IF(L37>1,L37/100,L37),0)) | N37: =IF(M37="","",IF(M37>=90,"A",IF(M37>=80,"B",IF(M37>=70,"C",IF(M37>=60,"D","F"))))) | O37: N | W37: =CREW_LOG!C34 -> 5 | X37: =IFERROR(INDEX(#REF!,MATCH(CREW_LOG!C34,#REF!,0)),"") | Y37: =CREW_LOG!D34 -> Arlene Martinez | Z37: =CREW_LOG!E34 -> Checker | AA37: =CREW_LOG!O34 -> N | AB37: =CREW_LOG!H34 -> Y | AC37: =CREW_LOG!I34 -> 0
A38: =PASSDOWN!B2 -> 46078 | B38: =PASSDOWN!E2 -> 3rd | D38: Noe Rosas | E38: OT from 2nd | H38: Y | I38: OT from 2nd shift | J38: =IF(OR(A38="",B38="",C38="",G38=""),"",SUMIFS(EVENTS!$G$5:$G$204,EVENTS!$A$5:$A$204,A38,EVENTS!$B$5:$B$204,B38,EVENTS!$C$5:$C$204,C38,EVENTS!$H$5:$H$204,G38)) | K38: =IF(J38="","",MAX(0,1-J38/IF(PASSDOWN!$U$2="",720,PASSDOWN!$U$2))) | L38: =IFERROR(INDEX(PASSDOWN!$G$11:$G$15,MATCH(C38,PASSDOWN!$A$11:$A$15,0)),"") | M38: =IF(OR(K38="",L38=""),"",ROUND(100*K38*IF(L38>1,L38/100,L38),0)) | N38: =IF(M38="","",IF(M38>=90,"A",IF(M38>=80,"B",IF(M38>=70,"C",IF(M38>=60,"D","F"))))) | O38: Y | W38: =CREW_LOG!C35 -> 5 | X38: =IFERROR(INDEX(#REF!,MATCH(CREW_LOG!C35,#REF!,0)),"") | Y38: =CREW_LOG!D35 -> Angelina Childtveep | Z38: =CREW_LOG!E35 -> Labeler | AA38: =CREW_LOG!O35 -> N | AB38: =CREW_LOG!H35 -> Y | AC38: =CREW_LOG!I35 -> 0
A39: =PASSDOWN!B2 -> 46078 | B39: =PASSDOWN!E2 -> 3rd | D39: Risney Campos | E39: OT from 2nd | H39: Y | I39: OT from 2nd shift | J39: =IF(OR(A39="",B39="",C39="",G39=""),"",SUMIFS(EVENTS!$G$5:$G$204,EVENTS!$A$5:$A$204,A39,EVENTS!$B$5:$B$204,B39,EVENTS!$C$5:$C$204,C39,EVENTS!$H$5:$H$204,G39)) | K39: =IF(J39="","",MAX(0,1-J39/IF(PASSDOWN!$U$2="",720,PASSDOWN!$U$2))) | L39: =IFERROR(INDEX(PASSDOWN!$G$11:$G$15,MATCH(C39,PASSDOWN!$A$11:$A$15,0)),"") | M39: =IF(OR(K39="",L39=""),"",ROUND(100*K39*IF(L39>1,L39/100,L39),0)) | N39: =IF(M39="","",IF(M39>=90,"A",IF(M39>=80,"B",IF(M39>=70,"C",IF(M39>=60,"D","F"))))) | O39: Y | W39: =CREW_LOG!C36 -> 5 | X39: =IFERROR(INDEX(#REF!,MATCH(CREW_LOG!C36,#REF!,0)),"") | Y39: =CREW_LOG!D36 -> Adriana Dupairon | Z39: =CREW_LOG!E36 -> Traypacker | AA39: =CREW_LOG!O36 -> N | AB39: =CREW_LOG!H36 -> Y | AC39: =CREW_LOG!I36 -> 0
A40: =PASSDOWN!B2 -> 46078 | B40: =PASSDOWN!E2 -> 3rd | D40: Rafael Legra | E40: OT from 2nd | H40: Y | I40: OT from 2nd shift | J40: =IF(OR(A40="",B40="",C40="",G40=""),"",SUMIFS(EVENTS!$G$5:$G$204,EVENTS!$A$5:$A$204,A40,EVENTS!$B$5:$B$204,B40,EVENTS!$C$5:$C$204,C40,EVENTS!$H$5:$H$204,G40)) | K40: =IF(J40="","",MAX(0,1-J40/IF(PASSDOWN!$U$2="",720,PASSDOWN!$U$2))) | L40: =IFERROR(INDEX(PASSDOWN!$G$11:$G$15,MATCH(C40,PASSDOWN!$A$11:$A$15,0)),"") | M40: =IF(OR(K40="",L40=""),"",ROUND(100*K40*IF(L40>1,L40/100,L40),0)) | N40: =IF(M40="","",IF(M40>=90,"A",IF(M40>=80,"B",IF(M40>=70,"C",IF(M40>=60,"D","F"))))) | O40: Y | W40: =CREW_LOG!C37 -> 5 | X40: =IFERROR(INDEX(#REF!,MATCH(CREW_LOG!C37,#REF!,0)),"") | Y40: =CREW_LOG!D37 -> Vanessa Gonzalez | Z40: =CREW_LOG!E37 -> Palletizer | AA40: =CREW_LOG!O37 -> N | AB40: =CREW_LOG!H37 -> Y | AC40: =CREW_LOG!I37 -> 0
...

Sheet EVENTS
A1: Shift Events / Downtime / RCA Log
A2: Enter each downtime/event here (including quality/safety/housekeeping). Minutes can be typed directly, or use Start/End time. Columns 'RCA ID' and 'OPL Needed' are optional but help drive follow-up.
A4: Date | B4: Shift | C4: Line | D4: Event Type | E4: Start | F4: End | G4: Minutes | H4: Area/Machine | I4: Issue / What happened | J4: Action taken | K4: Result / Current condition | L4: Status | M4: Root Cause (short) | N4: Countermeasure / Next step | O4: Owner | P4: Due Date | Q4: OPL Needed | R4: RCA ID | S4: Notes | T4: _SortKey
T5: =IF($G5="","",$G5+ROW()/100000)
T6: =IF($G6="","",$G6+ROW()/100000)
T7: =IF($G7="","",$G7+ROW()/100000)
T8: =IF($G8="","",$G8+ROW()/100000)
T9: =IF($G9="","",$G9+ROW()/100000)
T10: =IF($G10="","",$G10+ROW()/100000)
T11: =IF($G11="","",$G11+ROW()/100000)
T12: =IF($G12="","",$G12+ROW()/100000)
T13: =IF($G13="","",$G13+ROW()/100000)
T14: =IF($G14="","",$G14+ROW()/100000)
T15: =IF($G15="","",$G15+ROW()/100000)
T16: =IF($G16="","",$G16+ROW()/100000)
... T204: =IF($G204="","",$G204+ROW()/100000)

Sheet REF
A1: Shifts | B1: Lines | C1: Y/N | D1: Status | E1: Area/Machine | F1: RateMode | G1: Std CPH (cases/hr) | H1: Std CPH value | J1: Line Priority | K1: Priority #
A2: 1st | B2: 1 | C2: Y | D2: Open | E2: Start up | F2: Manual CPH | G2: 1 | J2: 1 | K2: 1
A3: 2nd | B3: 2 | C3: N | D3: Monitoring | E3: Depal | F3: Std CPH x OEE | G3: 2 | J3: 2 | K3: 2
A4: 3rd | B4: 3 | D4: Resolved | E4: Inspection Equipment | F4: Std CPH | G4: 3 | J4: 4 | K4: 3
B5: 4 | D5: Closed | E5: Conveyers | G5: 4 | J5: 3 | K5: 4
B6: 5 | E6: Bear Labeler | G6: 5 | J6: 5 | K6: 5
E7: Labeler A
E8: Labeler B
E9: Tray Packer
E10: Case Turner
E11: Langguth Labeler
E12: RA Jones
E13: Douglas Tray Packer
E14: Set-up
E15: Ryson Spiral
E16: Accumulation table
E17: Diagraph Print and Apply
E18: Product Quality
... E33: Other

Sheet Staffing-02-25-26
B1: 3rd Shift (2300-0700) 2nd shift Plus OT | X1: Staffing Sheet 3rd shift
B2: Label Line | X2: Name | Y2: Y/N | Z2: Emp ID | AA2: Name | AB2: Y/N
B3: Line 1 | E3: Line 2-8pk | H3: Line 3 | X3: Joshua Perkins | Z3: 945 | AA3: Richard Lowe
B4: Checker | C4: Reuben Callamco | E4: Checker | F4: Kenny Bryant | H4: Checker | I4: Dan Martinez | X4: Daniel Martinez | Z4: 948 | AA4: Lorena Velasco-Ochoa
B5: Depal | C5: Marilu | E5: Depal | F5: Mayra Cacique | H5: Depal | I5: Netafil Belmonte | X5: Steven Peterson | Z5: 952 | AA5: Angelina Childtaveep
B6: Labeler | C6: Maria Balzcar | E6: Labeler A | F6: Gloria | H6: Labeler | I6: Melesio Velazco | X6: Kenneth Bryant | Z6: 957 | AA6: Maria Graciano Reyes
